Workbook

Sheet Resumen
A1: Rendimiento metálico
A2: Fuente: Consumo_lotes_de_produccion.csv + Datos_productos.xlsx · generado 24-09-2026 12:17
A4: Rendimiento metálico (ponderado) | B4: =SUMIFS(Ordenes!$P$2:$P$840,Ordenes!$T$2:$T$840,"Válida")/SUMIFS(Ordenes!$Q$2:$Q$840,Ordenes!$T$2:$T$840,"Válida")
A5: Meta ponderada | B5: =SUMIFS(Ordenes!$V$2:$V$840,Ordenes!$T$2:$T$840,"Válida")/SUMIFS(Ordenes!$Q$2:$Q$840,Ordenes!$T$2:$T$840,"Válida")
A6: Diferencia vs meta (pp) | B6: =(B4-B5)*100
A7: Kg producidos | B7: =SUMIFS(Ordenes!$P$2:$P$840,Ordenes!$T$2:$T$840,"Válida")
A8: Kg consumidos | B8: =SUMIFS(Ordenes!$Q$2:$Q$840,Ordenes!$T$2:$T$840,"Válida")
A9: Pérdida metálica (kg) | B9: =B8-B7
A10: Órdenes válidas | B10: =COUNTIFS(Ordenes!$T$2:$T$840,"Válida")
A11: Órdenes a corregir (> 100 %) | B11: =COUNTIFS(Ordenes!$T$2:$T$840,"A corregir")
A14: Hojas
A15: • Ordenes: todas las órdenes del CSV, con grupo, medidas (mm), largo (m), rendimiento y estado. Base de todo el libro.
A16: • Carta mensual / Carta semanal / Carta diaria: carta de control I-MR con gráfico y el % de cada punto. Las celdas amarillas filtran por grupo o producto.
A17: • Grupo x semana: rendimiento de cada grupo por semana ISO (lunes a domingo), con meta y kg.
A18: • Grupo x día: rendimiento de cada grupo por día, con meta y kg.
A19: • Grupo x mes: rendimiento, kg producidos y meta por grupo y mes.
A20: • Ranking productos: productos de mayor a menor kg producidos.
A21: • A corregir: órdenes sobre 100 %, excluidas de los cálculos.
A22: • Productos: catálogo con medidas y datos del maestro.
A24: Reglas
A25: • Rend. met. = kg producidos / kg consumidos (sin despunte ni laminilla).
A26: • Rendimiento de un período o grupo = Σ kg producidos / Σ kg consumidos de las órdenes válidas.
... A40: • REDONDO LISO 1' 6M A615 GR60(P) → Redondo liso

Sheet Ordenes
A1: Orden | B1: Fecha inicio | C1: Fecha | D1: Año | E1: Mes | F1: Grupo | G1: Producto | H1: Material original (CSV) | I1: Formato (maestro) | J1: Código (maestro) | K1: Diámetro (mm) | L1: Ancho (mm) | M1: Espesor (mm) | N1: Lado (mm) | O1: Largo (m) | P1: Kg producidos | Q1: Kg consumidos | R1: Rend. met. | S1: Meta (Rend_Met) | T1: Estado | U1: Pérdida (kg) | V1: Meta × Kg cons | W1: Año ISO | X1: Semana ISO | Y1: Semana
A2: 43046145 | B2: 46024.383 | C2: 46024 | D2: =YEAR(C2) | E2: =MONTH(C2) | F2: B Hormigón | G2: B HORMIGON 18MM 12M A630-420H (N) | H2: B HORMIGON 18MM 12M A630-420H (N) | I2: RED 18 CR | J2: 110002938 | K2: 18 | O2: 12 | P2: 43702 | Q2: 47480.4 | R2: =IFERROR(P2/Q2,"") | S2: 0.96 | T2: =IF(R2>1,"A corregir","Válida") | U2: =Q2-P2 | V2: =IF(S2="",0,S2*Q2) | W2: 2026 | X2: 1 | Y2: 2026-S01
A3: 43046081 | B3: 46024.452 | C3: 46024 | D3: =YEAR(C3) | E3: =MONTH(C3) | F3: B Hormigón | G3: B HORMIGON 18MM 12M A630-420H (N) | H3: B HORMIGON 18MM 12M A630-420H (N) | I3: RED 18 CR | J3: 110002938 | K3: 18 | O3: 12 | P3: 125108 | Q3: 133293.6 | R3: =IFERROR(P3/Q3,"") | S3: 0.96 | T3: =IF(R3>1,"A corregir","Válida") | U3: =Q3-P3 | V3: =IF(S3="",0,S3*Q3) | W3: 2026 | X3: 1 | Y3: 2026-S01
A4: 43046082 | B4: 46024.692 | C4: 46024 | D4: =YEAR(C4) | E4: =MONTH(C4) | F4: B Hormigón | G4: B HORMIGON 18MM 11M A630-420H (N) | H4: B HORMIGON 18MM 11M A630-420H (N) | I4: RED 18 CR | J4: 110002937 | K4: 18 | O4: 11 | P4: 227051 | Q4: 237864 | R4: =IFERROR(P4/Q4,"") | S4: 0.96 | T4: =IF(R4>1,"A corregir","Válida") | U4: =Q4-P4 | V4: =IF(S4="",0,S4*Q4) | W4: 2026 | X4: 1 | Y4: 2026-S01
A5: 43046144 | B5: 46025.151 | C5: 46025 | D5: =YEAR(C5) | E5: =MONTH(C5) | F5: B Hormigón | G5: B HORMIGON 18MM 10M A630-420H (N) | H5: B HORMIGON 18MM 10M A630-420H (N) | I5: RED 18 CR | J5: 110002924 | K5: 18 | O5: 10 | P5: 42168 | Q5: 44880 | R5: =IFERROR(P5/Q5,"") | S5: 0.96 | T5: =IF(R5>1,"A corregir","Válida") | U5: =Q5-P5 | V5: =IF(S5="",0,S5*Q5) | W5: 2026 | X5: 1 | Y5: 2026-S01
A6: 43046083 | B6: 46025.23 | C6: 46025 | D6: =YEAR(C6) | E6: =MONTH(C6) | F6: B Hormigón | G6: B HORMIGON 18MM 9M A630-420H (N) | H6: B HORMIGON 18MM 9M A630-420H (N) | I6: RED 18 CR | J6: 110002951 | K6: 18 | O6: 9 | P6: 55745 | Q6: 59241.6 | R6: =IFERROR(P6/Q6,"") | S6: 0.959 | T6: =IF(R6>1,"A corregir","Válida") | U6: =Q6-P6 | V6: =IF(S6="",0,S6*Q6) | W6: 2026 | X6: 1 | Y6: 2026-S01
A7: 43046084 | B7: 46025.354 | C7: 46025 | D7: =YEAR(C7) | E7: =MONTH(C7) | F7: B Hormigón | G7: B HORMIGON 18MM 8M A630-420H (N) | H7: B HORMIGON 18MM 8M A630-420H (N) | I7: RED 18 CR | J7: 110002952 | K7: 18 | O7: 8 | P7: 22669 | Q7: 24235.2 | R7: =IFERROR(P7/Q7,"") | S7: 0.96 | T7: =IF(R7>1,"A corregir","Válida") | U7: =Q7-P7 | V7: =IF(S7="",0,S7*Q7) | W7: 2026 | X7: 1 | Y7: 2026-S01
A8: 43046085 | B8: 46025.408 | C8: 46025 | D8: =YEAR(C8) | E8: =MONTH(C8) | F8: B Hormigón | G8: B HORMIGON 18MM 7M A630-420H (N) | H8: B HORMIGON 18MM 7M A630-420H (N) | I8: RED 18 CR | J8: 110002940 | K8: 18 | O8: 7 | P8: 31676 | Q8: 33660 | R8: =IFERROR(P8/Q8,"") | S8: 0.959 | T8: =IF(R8>1,"A corregir","Válida") | U8: =Q8-P8 | V8: =IF(S8="",0,S8*Q8) | W8: 2026 | X8: 1 | Y8: 2026-S01
A9: 43046086 | B9: 46025.468 | C9: 46025 | D9: =YEAR(C9) | E9: =MONTH(C9) | F9: B Hormigón | G9: B HORMIGON 18MM 6M A630-420H (N) | H9: B HORMIGON 18MM 6M A630-420H (N) | I9: RED 18 CR | J9: 110002942 | K9: 18 | O9: 6 | P9: 80445 | Q9: 84823.2 | R9: =IFERROR(P9/Q9,"") | S9: 0.96 | T9: =IF(R9>1,"A corregir","Válida") | U9: =Q9-P9 | V9: =IF(S9="",0,S9*Q9) | W9: 2026 | X9: 1 | Y9: 2026-S01
A10: 43046087 | B10: 46025.653 | C10: 46025 | D10: =YEAR(C10) | E10: =MONTH(C10) | F10: B Hormigón | G10: B HORMIGON 18MM 12M A630-420HS (N) | H10: B HORMIGON 18MM 12M A630-420HS (N) | I10: RED 18 CR | J10: 110007120 | K10: 18 | O10: 12 | P10: 134976 | Q10: 143616 | R10: =IFERROR(P10/Q10,"") | S10: 0.95 | T10: =IF(R10>1,"A corregir","Válida") | U10: =Q10-P10 | V10: =IF(S10="",0,S10*Q10) | W10: 2026 | X10: 1 | Y10: 2026-S01
A11: 43046088 | B11: 46027.277 | C11: 46027 | D11: =YEAR(C11) | E11: =MONTH(C11) | F11: B Hormigón | G11: B HORMIGON 18MM 11M A630-420HS (N) | H11: B HORMIGON 18MM 11M A630-420HS (N) | I11: RED 18 CR | J11: 110007314 | K11: 18 | O11: 11 | P11: 29326 | Q11: 28723.2 | R11: =IFERROR(P11/Q11,"") | S11: 0.95 | T11: =IF(R11>1,"A corregir","Válida") | U11: =Q11-P11 | V11: =IF(S11="",0,S11*Q11) | W11: 2026 | X11: 2 | Y11: 2026-S02
A12: 43046089 | B12: 46027.465 | C12: 46027 | D12: =YEAR(C12) | E12: =MONTH(C12) | F12: B Hormigón | G12: B HORMIGON 32MM 12M A630-420H (N) | H12: B HORMIGON 32MM 12M A630-420H (N) | I12: RED 32 CR | J12: 110002900 | K12: 32 | O12: 12 | P12: 198647 | Q12: 214236 | R12: =IFERROR(P12/Q12,"") | S12: 0.96 | T12: =IF(R12>1,"A corregir","Válida") | U12: =Q12-P12 | V12: =IF(S12="",0,S12*Q12) | W12: 2026 | X12: 2 | Y12: 2026-S02
A13: 43046092 | B13: 46028.117 | C13: 46028 | D13: =YEAR(C13) | E13: =MONTH(C13) | F13: Saferock | G13: SAFEROCK 25MM 12M A420 | H13: SAFEROCK 25MM 12M A420 | I13: SFR 25 | J13: 106025583 | K13: 25 | O13: 12 | P13: 72482 | Q13: 78540 | R13: =IFERROR(P13/Q13,"") | S13: 0.953 | T13: =IF(R13>1,"A corregir","Válida") | U13: =Q13-P13 | V13: =IF(S13="",0,S13*Q13) | W13: 2026 | X13: 2 | Y13: 2026-S02
... A17: 43046090 | B17: 46028.534 | C17: 46028 | D17: =YEAR(C17) | E17: =MONTH(C17) | F17: Saferock | G17: SAFEROCK 25MM 12M A520D | H17: SAFEROCK 25MM 12M A520D | I17: SFR 25 | J17: 119506719 | K17: 25 | O17: 12 | P17: 23250 | Q17: 24684 | R17: =IFERROR(P17/Q17,"") | S17: 0.97 | T17: =IF(R17>1,"A corregir","Válida") | U17: =Q17-P17 | V17: =IF(S17="",0,S17*Q17) | W17: 2026 | X17: 2 | Y17: 2026-S02
A18: 43046096 | B18: 46028.898 | C18: 46028 | D18: =YEAR(C18) | E18: =MONTH(C18) | F18: Ángulo | G18: ANG 75X75X6MM 12M ASTM A572 T2 (N) | H18: ANG SEMI 75X75X6MM 12M ASTM A572 T2 (N) | I18: ANG 75 x 6 | J18: 119502820 | L18: 75 | M18: 6 | O18: 12 | P18: 21894 | Q18: 25581.6 | R18: =IFERROR(P18/Q18,"") | S18: 0.97 | T18: =IF(R18>1,"A corregir","Válida") | U18: =Q18-P18 | V18: =IF(S18="",0,S18*Q18) | W18: 2026 | X18: 2 | Y18: 2026-S02
A19: 43046097 | B19: 46029.019 | C19: 46029 | D19: =YEAR(C19) | E19: =MONTH(C19) | F19: Ángulo | G19: ANGULO 80X80X8MM A270ES | H19: ANGULO SEMI 80X80X8MM A270ES | I19: ANG 80 x 8 | J19: 106501049 | L19: 80 | M19: 8 | O19: 6 | P19: 60255 | Q19: 65524.8 | R19: =IFERROR(P19/Q19,"") | S19: 0.934 | T19: =IF(R19>1,"A corregir","Válida") | U19: =Q19-P19 | V19: =IF(S19="",0,S19*Q19) | W19: 2026 | X19: 2 | Y19: 2026-S02
A20: 43046098 | B20: 46029.291 | C20: 46029 | D20: =YEAR(C20) | E20: =MONTH(C20) | F20: Ángulo | G20: ANGULO 80X80X6MM A270ES | H20: ANGULO SEMI 80X80X6MM A270ES | I20: ANG 80 x 6 | J20: 106501050 | L20: 80 | M20: 6 | O20: 6 | P20: 28006 | Q20: 35904 | R20: =IFERROR(P20/Q20,"") | S20: 0.949 | T20: =IF(R20>1,"A corregir","Válida") | U20: =Q20-P20 | V20: =IF(S20="",0,S20*Q20) | W20: 2026 | X20: 2 | Y20: 2026-S02
A21: 43046237 | B21: 46029.76 | C21: 46029 | D21: =YEAR(C21) | E21: =MONTH(C21) | F21: Plana | G21: PLANA 25X3MM 6M A270ES (N) | H21: PLANA 25X3MM 6M A270ES (N) | I21: PL 25 x 3 | J21: 109013858 | L21: 25 | M21: 3 | O21: 6 | P21: 60365 | Q21: 65841.6 | R21: =IFERROR(P21/Q21,"") | S21: 0.968 | T21: =IF(R21>1,"A corregir","Válida") | U21: =Q21-P21 | V21: =IF(S21="",0,S21*Q21) | W21: 2026 | X21: 2 | Y21: 2026-S02
A22: 43046238 | B22: 46030.163 | C22: 46030 | D22: =YEAR(C22) | E22: =MONTH(C22) | F22: Cuadrado | G22: CUADRADO 10MM 6M COMERCIAL (N) | H22: CUADRADO 10MM 6M COMERCIAL (N) | I22: CUAD 10 | J22: 109007066 | N22: 10 | O22: 6 | P22: 78534 | Q22: 84216 | R22: =IFERROR(P22/Q22,"") | S22: 0.967 | T22: =IF(R22>1,"A corregir","Válida") | U22: =Q22-P22 | V22: =IF(S22="",0,S22*Q22) | W22: 2026 | X22: 2 | Y22: 2026-S02
A23: 43046240 | B23: 46030.428 | C23: 46030 | D23: =YEAR(C23) | E23: =MONTH(C23) | F23: Plana | G23: PLANA 20X5MM 6M A270ES (N) | H23: PLANA 20X5MM 6M A270ES (N) | I23: PL 20 x 5 | J23: 119502244 | L23: 20 | M23: 5 | O23: 6 | P23: 31293 | Q23: 33303.6 | R23: =IFERROR(P23/Q23,"") | S23: 0.967 | T23: =IF(R23>1,"A corregir","Válida") | U23: =Q23-P23 | V23: =IF(S23="",0,S23*Q23) | W23: 2026 | X23: 2 | Y23: 2026-S02
A24: 43046241 | B24: 46030.705 | C24: 46030 | D24: =YEAR(C24) | E24: =MONTH(C24) | F24: Ángulo | G24: ANGULO 20X20X3MM A270ES | H24: ANGULO SEMI 20X20X3MM A270ES | I24: ANG 20 x 3 | J24: 106501016 | L24: 20 | M24: 3 | O24: 12 | P24: 102257 | Q24: 106444.8 | R24: =IFERROR(P24/Q24,"") | S24: 0.963 | T24: =IF(R24>1,"A corregir","Válida") | U24: =Q24-P24 | V24: =IF(S24="",0,S24*Q24) | W24: 2026 | X24: 2 | Y24: 2026-S02
A25: 43046244 | B25: 46031.301 | C25: 46031 | D25: =YEAR(C25) | E25: =MONTH(C25) | F25: Plana | G25: PLANA 38X3MM 6M A270ES (N) | H25: PLANA 38X3MM 6M A270ES (N) | I25: PL 38 x 3 | J25: 109013904 | L25: 38 | M25: 3 | O25: 6 | P25: 75178 | Q25: 78988.8 | R25: =IFERROR(P25/Q25,"") | S25: 0.966 | T25: =IF(R25>1,"A corregir","Válida") | U25: =Q25-P25 | V25: =IF(S25="",0,S25*Q25) | W25: 2026 | X25: 2 | Y25: 2026-S02
A26: 43046245 | B26: 46031.594 | C26: 46031 | D26: =YEAR(C26) | E26: =MONTH(C26) | F26: Plana | G26: PLANA 32X5MM 6M A270ES (N) | H26: PLANA 32X5MM 6M A270ES (N) | I26: PL 32 x 5 | J26: 109013897 | L26: 32 | M26: 5 | O26: 6 | P26: 30541 | Q26: 32524.8 | R26: =IFERROR(P26/Q26,"") | S26: 0.966 | T26: =IF(R26>1,"A corregir","Válida") | U26: =Q26-P26 | V26: =IF(S26="",0,S26*Q26) | W26: 2026 | X26: 2 | Y26: 2026-S02
A27: 43046246 | B27: 46031.773 | C27: 46031 | D27: =YEAR(C27) | E27: =MONTH(C27) | F27: Ángulo | G27: ANGULO 25X25X5MM A270ES | H27: ANGULO SEMI 25X25X5MM A270ES | I27: ANG 25 x 5 | J27: 106501812 | L27: 25 | M27: 5 | O27: 12 | P27: 30817 | Q27: 34557.6 | R27: =IFERROR(P27/Q27,"") | S27: 0.961 | T27: =IF(R27>1,"A corregir","Válida") | U27: =Q27-P27 | V27: =IF(S27="",0,S27*Q27) | W27: 2026 | X27: 2 | Y27: 2026-S02
A28: 43046272 | B28: 46031.96 | C28: 46031 | D28: =YEAR(C28) | E28: =MONTH(C28) | F28: Ángulo | G28: ANGULO 25X25X3MM A270ES | H28: ANGULO SEMI 25X25X3MM A270ES | I28: ANG 25 x 3 | J28: 106501017 | L28: 25 | M28: 3 | O28: 12 | P28: 128307 | Q28: 134640 | R28: =IFERROR(P28/Q28,"") | S28: 0.963 | T28: =IF(R28>1,"A corregir","Válida") | U28: =Q28-P28 | V28: =IF(S28="",0,S28*Q28) | W28: 2026 | X28: 2 | Y28: 2026-S02
A29: 43046248 | B29: 46032.305 | C29: 46032 | D29: =YEAR(C29) | E29: =MONTH(C29) | F29: Redondo liso | G29: REDONDO LISO 5/8' 6M SAE 1020 (N) | H29: REDONDO LISO 5/8' 6M SAE 1020 (N) | I29: RED 16 | J29: 109006913 | K29: 15.9 | O29: 6 | P29: 20226 | Q29: 22440 | R29: =IFERROR(P29/Q29,"") | S29: 0.959 | T29: =IF(R29>1,"A corregir","Válida") | U29: =Q29-P29 | V29: =IF(S29="",0,S29*Q29) | W29: 2026 | X29: 2 | Y29: 2026-S02
A30: 43046249 | B30: 46032.347 | C30: 46032 | D30: =YEAR(C30) | E30: =MONTH(C30) | F30: Redondo liso | G30: REDONDO LISO 16MM 6M SAE 1020 (N) | H30: REDONDO LISO 16MM 6M SAE 1020 (N) | I30: RED 16 | J30: 119502683 | K30: 16 | O30: 6 | P30: 26674 | Q30: 28274.4 | R30: =IFERROR(P30/Q30,"") | S30: 0.958 | T30: =IF(R30>1,"A corregir","Válida") | U30: =Q30-P30 | V30: =IF(S30="",0,S30*Q30) | W30: 2026 | X30: 2 | Y30: 2026-S02
A31: 43046250 | B31: 46032.444 | C31: 46032 | D31: =YEAR(C31) | E31: =MONTH(C31) | F31: B Hormigón | G31: B HORMIGON 16MM 6M A630-420H (N) | H31: B HORMIGON 16MM 6M A630-420H (N) | I31: RED 16 CR | J31: 110002928 | K31: 16 | O31: 6 | P31: 169988 | Q31: 177724.8 | R31: =IFERROR(P31/Q31,"") | S31: 0.965 | T31: =IF(R31>1,"A corregir","Válida") | U31: =Q31-P31 | V31: =IF(S31="",0,S31*Q31) | W31: 2026 | X31: 2 | Y31: 2026-S02
A32: 43046273 | B32: 46034.308 | C32: 46034 | D32: =YEAR(C32) | E32: =MONTH(C32) | F32: B Hormigón | G32: B HORMIGON 16MM 6M A630-420H (N) | H32: B HORMIGON 16MM 6M A630-420H (N) | I32: RED 16 CR | J32: 110002928 | K32: 16 | O32: 6 | P32: 56350 | Q32: 59241.6 | R32: =IFERROR(P32/Q32,"") | S32: 0.965 | T32: =IF(R32>1,"A corregir","Válida") | U32: =Q32-P32 | V32: =IF(S32="",0,S32*Q32) | W32: 2026 | X32: 3 | Y32: 2026-S03
A33: 43046301 | B33: 46034.46 | C33: 46034 | D33: =YEAR(C33) | E33: =MONTH(C33) | F33: Cuadrado | G33: CUADRADO 14MM 6M COMERCIAL (N) | H33: CUADRADO 14MM 6M COMERCIAL (N) | I33: CUAD 14 | J33: 109007064 | N33: 14 | O33: 6 | P33: 32676 | Q33: 35006.4 | R33: =IFERROR(P33/Q33,"") | S33: 0.966 | T33: =IF(R33>1,"A corregir","Válida") | U33: =Q33-P33 | V33: =IF(S33="",0,S33*Q33) | W33: 2026 | X33: 3 | Y33: 2026-S03
A34: 43046317 | B34: 46034.699 | C34: 46034 | D34: =YEAR(C34) | E34: =MONTH(C34) | F34: Plana | G34: PLANA 38X5MM 6M A270ES (N) | H34: PLANA 38X5MM 6M A270ES (N) | I34: PL 38 x 5 | J34: 109013914 | L34: 38 | M34: 5 | O34: 6 | P34: 122391 | Q34: 124317.6 | R34: =IFERROR(P34/Q34,"") | S34: 0.965 | T34: =IF(R34>1,"A corregir","Válida") | U34: =Q34-P34 | V34: =IF(S34="",0,S34*Q34) | W34: 2026 | X34: 3 | Y34: 2026-S03
A35: 43046303 | B35: 46035.013 | C35: 46035 | D35: =YEAR(C35) | E35: =MONTH(C35) | F35: Plana | G35: PLANA 38X5MM 6M A270ES (N) | H35: PLANA 38X5MM 6M A270ES (N) | I35: PL 38 x 5 | J35: 109013914 | L35: 38 | M35: 5 | O35: 6 | P35: 13017 | Q35: 14361.6 | R35: =IFERROR(P35/Q35,"") | S35: 0.965 | T35: =IF(R35>1,"A corregir","Válida") | U35: =Q35-P35 | V35: =IF(S35="",0,S35*Q35) | W35: 2026 | X35: 3 | Y35: 2026-S03
A36: 43046325 | B36: 46035.215 | C36: 46035 | D36: =YEAR(C36) | E36: =MONTH(C36) | F36: Ángulo | G36: ANGULO 30X30X3MM A270ES | H36: ANGULO SEMI 30X30X3MM A270ES | I36: ANG 30 x 3 | J36: 106501029 | L36: 30 | M36: 3 | O36: 6 | P36: 180909 | Q36: 198369.6 | R36: =IFERROR(P36/Q36,"") | S36: 0.96 | T36: =IF(R36>1,"A corregir","Válida") | U36: =Q36-P36 | V36: =IF(S36="",0,S36*Q36) | W36: 2026 | X36: 3 | Y36: 2026-S03
A37: 43046327 | B37: 46035.894 | C37: 46035 | D37: =YEAR(C37) | E37: =MONTH(C37) | F37: Plana | G37: PLANA 50X3 MM 6M A270ES (N) | H37: PLANA 50X3 MM 6M A270ES (N) | I37: PL 50 x 3 | J37: 109013903 | L37: 50 | M37: 3 | O37: 6 | P37: 104709 | Q37: 114892.8 | R37: =IFERROR(P37/Q37,"") | S37: 0.963 | T37: =IF(R37>1,"A corregir","Válida") | U37: =Q37-P37 | V37: =IF(S37="",0,S37*Q37) | W37: 2026 | X37: 3 | Y37: 2026-S03
A38: 43046344 | B38: 46036.749 | C38: 46036 | D38: =YEAR(C38) | E38: =MONTH(C38) | F38: Ángulo | G38: ANGULO 40X40X4MM A270ES | H38: ANGULO SEMI 40X40X4MM A270ES | I38: ANG 40 x 4 | J38: 106501034 | L38: 40 | M38: 4 | O38: 6 | P38: 30247 | Q38: 33211.2 | R38: =IFERROR(P38/Q38,"") | S38: 0.953 | T38: =IF(R38>1,"A corregir","Válida") | U38: =Q38-P38 | V38: =IF(S38="",0,S38*Q38) | W38: 2026 | X38: 3 | Y38: 2026-S03
A39: 43046345 | B39: 46036.975 | C39: 46036 | D39: =YEAR(C39) | E39: =MONTH(C39) | F39: Ángulo | G39: ANGULO 40X40X3MM A270ES | H39: ANGULO SEMI 40X40X3MM A270ES | I39: ANG 40 x 3 | J39: 106501033 | L39: 40 | M39: 3 | O39: 6 | P39: 190119 | Q39: 205101.6 | R39: =IFERROR(P39/Q39,"") | S39: 0.957 | T39: =IF(R39>1,"A corregir","Válida") | U39: =Q39-P39 | V39: =IF(S39="",0,S39*Q39) | W39: 2026 | X39: 3 | Y39: 2026-S03
A40: 43046350 | B40: 46037.629 | C40: 46037 | D40: =YEAR(C40) | E40: =MONTH(C40) | F40: Ángulo | G40: ANGULO 40X40X3MM 6M A36 (AL) | H40: ANGULO SEMI 40X40X3MM 6M A36 (AL) | I40: ANG 40 X 3 | J40: 119502602 | L40: 40 | M40: 3 | O40: 6 | P40: 17970 | Q40: 19430.4 | R40: =IFERROR(P40/Q40,"") | S40: 0.97 | T40: =IF(R40>1,"A corregir","Válida") | U40: =Q40-P40 | V40: =IF(S40="",0,S40*Q40) | W40: 2026 | X40: 3 | Y40: 2026-S03
A41: 43046333 | B41: 46037.784 | C41: 46037 | D41: =YEAR(C41) | E41: =MONTH(C41) | F41: Ángulo | G41: ANGULO 50X50X4MM A270ES | H41: ANGULO SEMI 50X50X4MM A270ES | I41: ANG 50 x 4 | J41: 106501036 | L41: 50 | M41: 4 | O41: 6 | P41: 43862 | Q41: 48021.6 | R41: =IFERROR(P41/Q41,"") | S41: 0.948 | T41: =IF(R41>1,"A corregir","Válida") | U41: =Q41-P41 | V41: =IF(S41="",0,S41*Q41) | W41: 2026 | X41: 3 | Y41: 2026-S03
A42: 43046336 | B42: 46037.961 | C42: 46037 | D42: =YEAR(C42) | E42: =MONTH(C42) | F42: Ángulo | G42: ANGULO 50X50X3MM A270ES | H42: ANGULO SEMI 50X50X3MM A270ES | I42: ANG 50 x 3 | J42: 106501038 | L42: 50 | M42: 3 | O42: 6 | P42: 221125 | Q42: 239210.4 | R42: =IFERROR(P42/Q42,"") | S42: 0.953 | T42: =IF(R42>1,"A corregir","Válida") | U42: =Q42-P42 | V42: =IF(S42="",0,S42*Q42) | W42: 2026 | X42: 3 | Y42: 2026-S03
A43: 43046383 | B43: 46038.711 | C43: 46038 | D43: =YEAR(C43) | E43: =MONTH(C43) | F43: B Hormigón | G43: B HORMIGON 25MM 12M A630-420H (N) | H43: B HORMIGON 25MM 12M A630-420H (N) | I43: RED 25 CR | J43: 110002941 | K43: 25 | O43: 12 | P43: 62928 | Q43: 67082.4 | R43: =IFERROR(P43/Q43,"") | S43: 0.95 | T43: =IF(R43>1,"A corregir","Válida") | U43: =Q43-P43 | V43: =IF(S43="",0,S43*Q43) | W43: 2026 | X43: 3 | Y43: 2026-S03
...

Sheet Carta mensual
A1: Carta de control mensual
A2: Carta I-MR sobre el rendimiento ponderado (Σ kg producidos / Σ kg consumidos) de las órdenes válidas (≤ 100 %).
A4: Grupo: | B4: Todos | C4: ← elige un grupo de la lista (celda amarilla) o deja «Todos»
A5: Producto: | B5: Todos | C5: ← escribe el nombre exacto del producto (columna Producto de «Ordenes») o deja «Todos»
F7: LC (rend. ponderado) | G7: =IFERROR(SUM(E16:E24)/SUM(F16:F24),"") | H7: d2 = 1,128 es la constante de la carta I-MR para rangos móviles de 2 puntos.
F8: MR̄ (promedio rango móvil) | G8: =IFERROR(AVERAGE(J16:J24),"")
F9: σ = MR̄ / 1,128 | G9: =IFERROR(G8/1.128,"")
F10: LCS = LC + 3σ | G10: =IFERROR(G7+3*G9,"")
F11: LCI = LC − 3σ | G11: =IFERROR(G7-3*G9,"")
F12: Meta ponderada | G12: =IFERROR(SUMIFS(Ordenes!$V$2:$V$840,Ordenes!$T$2:$T$840,"Válida",Ordenes!$F$2:$F$840,IF($B$4="Todos","*",$B$4),Ordenes!$G$2:$G$840,IF($B$5="Todos","*",$B$5))/SUMIFS(Ordenes!$Q$2:$Q$840,Ordenes!$T$2:$T$840,"Válida",Ordenes!$F$2:$F$840,IF($B$4="Todos","*",$B$4),Ordenes!$G$2:$G$840,IF($B$5="Todos","*",$B$5)),"")
A15: Período | B15: Año | C15: Mes | D15: Órdenes válidas | E15: Kg producidos | F15: Kg consumidos | G15: Rend. met. | H15: Meta | I15: vs meta (pp) | J15: MR | K15: LC | L15: LCS | M15: LCI | N15: Estado | O15: Órdenes a corregir
A16: Ene 2026 | B16: 2026 | C16: 1 | D16: =COUNTIFS(Ordenes!$D$2:$D$840,$B16,Ordenes!$E$2:$E$840,$C16,Ordenes!$T$2:$T$840,"Válida",Ordenes!$F$2:$F$840,IF($B$4="Todos","*",$B$4),Ordenes!$G$2:$G$840,IF($B$5="Todos","*",$B$5)) | E16: =SUMIFS(Ordenes!$P$2:$P$840,Ordenes!$D$2:$D$840,$B16,Ordenes!$E$2:$E$840,$C16,Ordenes!$T$2:$T$840,"Válida",Ordenes!$F$2:$F$840,IF($B$4="Todos","*",$B$4),Ordenes!$G$2:$G$840,IF($B$5="Todos","*",$B$5)) | F16: =SUMIFS(Ordenes!$Q$2:$Q$840,Ordenes!$D$2:$D$840,$B16,Ordenes!$E$2:$E$840,$C16,Ordenes!$T$2:$T$840,"Válida",Ordenes!$F$2:$F$840,IF($B$4="Todos","*",$B$4),Ordenes!$G$2:$G$840,IF($B$5="Todos","*",$B$5)) | G16: =IF(F16=0,NA(),E16/F16) | H16: =IFERROR(SUMIFS(Ordenes!$V$2:$V$840,Ordenes!$D$2:$D$840,$B16,Ordenes!$E$2:$E$840,$C16,Ordenes!$T$2:$T$840,"Válida",Ordenes!$F$2:$F$840,IF($B$4="Todos","*",$B$4),Ordenes!$G$2:$G$840,IF($B$5="Todos","*",$B$5))/F16,NA()) | I16: =IFERROR((G16-H16)*100,"") | K16: =$G$7 | L16: =$G$10 | M16: =$G$11 | N16: =IF(ISNA(G16),"Sin producción",IF(L16="","Sin límites",IF(G16>L16,"▲ Sobre LCS",IF(G16<M16,"▼ Bajo LCI","En control")))) | O16: =COUNTIFS(Ordenes!$D$2:$D$840,$B16,Ordenes!$E$2:$E$840,$C16,Ordenes!$T$2:$T$840,"A corregir",Ordenes!$F$2:$F$840,IF($B$4="Todos","*",$B$4),Ordenes!$G$2:$G$840,IF($B$5="Todos","*",$B$5))
A17: Feb 2026 | B17: 2026 | C17: 2 | D17: =COUNTIFS(Ordenes!$D$2:$D$840,$B17,Ordenes!$E$2:$E$840,$C17,Ordenes!$T$2:$T$840,"Válida",Ordenes!$F$2:$F$840,IF($B$4="Todos","*",$B$4),Ordenes!$G$2:$G$840,IF($B$5="Todos","*",$B$5)) | E17: =SUMIFS(Ordenes!$P$2:$P$840,Ordenes!$D$2:$D$840,$B17,Ordenes!$E$2:$E$840,$C17,Ordenes!$T$2:$T$840,"Válida",Ordenes!$F$2:$F$840,IF($B$4="Todos","*",$B$4),Ordenes!$G$2:$G$840,IF($B$5="Todos","*",$B$5)) | F17: =SUMIFS(Ordenes!$Q$2:$Q$840,Ordenes!$D$2:$D$840,$B17,Ordenes!$E$2:$E$840,$C17,Ordenes!$T$2:$T$840,"Válida",Ordenes!$F$2:$F$840,IF($B$4="Todos","*",$B$4),Ordenes!$G$2:$G$840,IF($B$5="Todos","*",$B$5)) | G17: =IF(F17=0,NA(),E17/F17) | H17: =IFERROR(SUMIFS(Ordenes!$V$2:$V$840,Ordenes!$D$2:$D$840,$B17,Ordenes!$E$2:$E$840,$C17,Ordenes!$T$2:$T$840,"Válida",Ordenes!$F$2:$F$840,IF($B$4="Todos","*",$B$4),Ordenes!$G$2:$G$840,IF($B$5="Todos","*",$B$5))/F17,NA()) | I17: =IFERROR((G17-H17)*100,"") | J17: =IFERROR(ABS(G17-G16),"") | K17: =$G$7 | L17: =$G$10 | M17: =$G$11 | N17: =IF(ISNA(G17),"Sin producción",IF(L17="","Sin límites",IF(G17>L17,"▲ Sobre LCS",IF(G17<M17,"▼ Bajo LCI","En control")))) | O17: =COUNTIFS(Ordenes!$D$2:$D$840,$B17,Ordenes!$E$2:$E$840,$C17,Ordenes!$T$2:$T$840,"A corregir",Ordenes!$F$2:$F$840,IF($B$4="Todos","*",$B$4),Ordenes!$G$2:$G$840,IF($B$5="Todos","*",$B$5))
A18: Mar 2026 | B18: 2026 | C18: 3 | D18: =COUNTIFS(Ordenes!$D$2:$D$840,$B18,Ordenes!$E$2:$E$840,$C18,Ordenes!$T$2:$T$840,"Válida",Ordenes!$F$2:$F$840,IF($B$4="Todos","*",$B$4),Ordenes!$G$2:$G$840,IF($B$5="Todos","*",$B$5)) | E18: =SUMIFS(Ordenes!$P$2:$P$840,Ordenes!$D$2:$D$840,$B18,Ordenes!$E$2:$E$840,$C18,Ordenes!$T$2:$T$840,"Válida",Ordenes!$F$2:$F$840,IF($B$4="Todos","*",$B$4),Ordenes!$G$2:$G$840,IF($B$5="Todos","*",$B$5)) | F18: =SUMIFS(Ordenes!$Q$2:$Q$840,Ordenes!$D$2:$D$840,$B18,Ordenes!$E$2:$E$840,$C18,Ordenes!$T$2:$T$840,"Válida",Ordenes!$F$2:$F$840,IF($B$4="Todos","*",$B$4),Ordenes!$G$2:$G$840,IF($B$5="Todos","*",$B$5)) | G18: =IF(F18=0,NA(),E18/F18) | H18: =IFERROR(SUMIFS(Ordenes!$V$2:$V$840,Ordenes!$D$2:$D$840,$B18,Ordenes!$E$2:$E$840,$C18,Ordenes!$T$2:$T$840,"Válida",Ordenes!$F$2:$F$840,IF($B$4="Todos","*",$B$4),Ordenes!$G$2:$G$840,IF($B$5="Todos","*",$B$5))/F18,NA()) | I18: =IFERROR((G18-H18)*100,"") | J18: =IFERROR(ABS(G18-G17),"") | K18: =$G$7 | L18: =$G$10 | M18: =$G$11 | N18: =IF(ISNA(G18),"Sin producción",IF(L18="","Sin límites",IF(G18>L18,"▲ Sobre LCS",IF(G18<M18,"▼ Bajo LCI","En control")))) | O18: =COUNTIFS(Ordenes!$D$2:$D$840,$B18,Ordenes!$E$2:$E$840,$C18,Ordenes!$T$2:$T$840,"A corregir",Ordenes!$F$2:$F$840,IF($B$4="Todos","*",$B$4),Ordenes!$G$2:$G$840,IF($B$5="Todos","*",$B$5))
A19: Abr 2026 | B19: 2026 | C19: 4 | D19: =COUNTIFS(Ordenes!$D$2:$D$840,$B19,Ordenes!$E$2:$E$840,$C19,Ordenes!$T$2:$T$840,"Válida",Ordenes!$F$2:$F$840,IF($B$4="Todos","*",$B$4),Ordenes!$G$2:$G$840,IF($B$5="Todos","*",$B$5)) | E19: =SUMIFS(Ordenes!$P$2:$P$840,Ordenes!$D$2:$D$840,$B19,Ordenes!$E$2:$E$840,$C19,Ordenes!$T$2:$T$840,"Válida",Ordenes!$F$2:$F$840,IF($B$4="Todos","*",$B$4),Ordenes!$G$2:$G$840,IF($B$5="Todos","*",$B$5)) | F19: =SUMIFS(Ordenes!$Q$2:$Q$840,Ordenes!$D$2:$D$840,$B19,Ordenes!$E$2:$E$840,$C19,Ordenes!$T$2:$T$840,"Válida",Ordenes!$F$2:$F$840,IF($B$4="Todos","*",$B$4),Ordenes!$G$2:$G$840,IF($B$5="Todos","*",$B$5)) | G19: =IF(F19=0,NA(),E19/F19) | H19: =IFERROR(SUMIFS(Ordenes!$V$2:$V$840,Ordenes!$D$2:$D$840,$B19,Ordenes!$E$2:$E$840,$C19,Ordenes!$T$2:$T$840,"Válida",Ordenes!$F$2:$F$840,IF($B$4="Todos","*",$B$4),Ordenes!$G$2:$G$840,IF($B$5="Todos","*",$B$5))/F19,NA()) | I19: =IFERROR((G19-H19)*100,"") | J19: =IFERROR(ABS(G19-G18),"") | K19: =$G$7 | L19: =$G$10 | M19: =$G$11 | N19: =IF(ISNA(G19),"Sin producción",IF(L19="","Sin límites",IF(G19>L19,"▲ Sobre LCS",IF(G19<M19,"▼ Bajo LCI","En control")))) | O19: =COUNTIFS(Ordenes!$D$2:$D$840,$B19,Ordenes!$E$2:$E$840,$C19,Ordenes!$T$2:$T$840,"A corregir",Ordenes!$F$2:$F$840,IF($B$4="Todos","*",$B$4),Ordenes!$G$2:$G$840,IF($B$5="Todos","*",$B$5))
A20: May 2026 | B20: 2026 | C20: 5 | D20: =COUNTIFS(Ordenes!$D$2:$D$840,$B20,Ordenes!$E$2:$E$840,$C20,Ordenes!$T$2:$T$840,"Válida",Ordenes!$F$2:$F$840,IF($B$4="Todos","*",$B$4),Ordenes!$G$2:$G$840,IF($B$5="Todos","*",$B$5)) | E20: =SUMIFS(Ordenes!$P$2:$P$840,Ordenes!$D$2:$D$840,$B20,Ordenes!$E$2:$E$840,$C20,Ordenes!$T$2:$T$840,"Válida",Ordenes!$F$2:$F$840,IF($B$4="Todos","*",$B$4),Ordenes!$G$2:$G$840,IF($B$5="Todos","*",$B$5)) | F20: =SUMIFS(Ordenes!$Q$2:$Q$840,Ordenes!$D$2:$D$840,$B20,Ordenes!$E$2:$E$840,$C20,Ordenes!$T$2:$T$840,"Válida",Ordenes!$F$2:$F$840,IF($B$4="Todos","*",$B$4),Ordenes!$G$2:$G$840,IF($B$5="Todos","*",$B$5)) | G20: =IF(F20=0,NA(),E20/F20) | H20: =IFERROR(SUMIFS(Ordenes!$V$2:$V$840,Ordenes!$D$2:$D$840,$B20,Ordenes!$E$2:$E$840,$C20,Ordenes!$T$2:$T$840,"Válida",Ordenes!$F$2:$F$840,IF($B$4="Todos","*",$B$4),Ordenes!$G$2:$G$840,IF($B$5="Todos","*",$B$5))/F20,NA()) | I20: =IFERROR((G20-H20)*100,"") | J20: =IFERROR(ABS(G20-G19),"") | K20: =$G$7 | L20: =$G$10 | M20: =$G$11 | N20: =IF(ISNA(G20),"Sin producción",IF(L20="","Sin límites",IF(G20>L20,"▲ Sobre LCS",IF(G20<M20,"▼ Bajo LCI","En control")))) | O20: =COUNTIFS(Ordenes!$D$2:$D$840,$B20,Ordenes!$E$2:$E$840,$C20,Ordenes!$T$2:$T$840,"A corregir",Ordenes!$F$2:$F$840,IF($B$4="Todos","*",$B$4),Ordenes!$G$2:$G$840,IF($B$5="Todos","*",$B$5))
A21: Jun 2026 | B21: 2026 | C21: 6 | D21: =COUNTIFS(Ordenes!$D$2:$D$840,$B21,Ordenes!$E$2:$E$840,$C21,Ordenes!$T$2:$T$840,"Válida",Ordenes!$F$2:$F$840,IF($B$4="Todos","*",$B$4),Ordenes!$G$2:$G$840,IF($B$5="Todos","*",$B$5)) | E21: =SUMIFS(Ordenes!$P$2:$P$840,Ordenes!$D$2:$D$840,$B21,Ordenes!$E$2:$E$840,$C21,Ordenes!$T$2:$T$840,"Válida",Ordenes!$F$2:$F$840,IF($B$4="Todos","*",$B$4),Ordenes!$G$2:$G$840,IF($B$5="Todos","*",$B$5)) | F21: =SUMIFS(Ordenes!$Q$2:$Q$840,Ordenes!$D$2:$D$840,$B21,Ordenes!$E$2:$E$840,$C21,Ordenes!$T$2:$T$840,"Válida",Ordenes!$F$2:$F$840,IF($B$4="Todos","*",$B$4),Ordenes!$G$2:$G$840,IF($B$5="Todos","*",$B$5)) | G21: =IF(F21=0,NA(),E21/F21) | H21: =IFERROR(SUMIFS(Ordenes!$V$2:$V$840,Ordenes!$D$2:$D$840,$B21,Ordenes!$E$2:$E$840,$C21,Ordenes!$T$2:$T$840,"Válida",Ordenes!$F$2:$F$840,IF($B$4="Todos","*",$B$4),Ordenes!$G$2:$G$840,IF($B$5="Todos","*",$B$5))/F21,NA()) | I21: =IFERROR((G21-H21)*100,"") | J21: =IFERROR(ABS(G21-G20),"") | K21: =$G$7 | L21: =$G$10 | M21: =$G$11 | N21: =IF(ISNA(G21),"Sin producción",IF(L21="","Sin límites",IF(G21>L21,"▲ Sobre LCS",IF(G21<M21,"▼ Bajo LCI","En control")))) | O21: =COUNTIFS(Ordenes!$D$2:$D$840,$B21,Ordenes!$E$2:$E$840,$C21,Ordenes!$T$2:$T$840,"A corregir",Ordenes!$F$2:$F$840,IF($B$4="Todos","*",$B$4),Ordenes!$G$2:$G$840,IF($B$5="Todos","*",$B$5))
A22: Jul 2026 | B22: 2026 | C22: 7 | D22: =COUNTIFS(Ordenes!$D$2:$D$840,$B22,Ordenes!$E$2:$E$840,$C22,Ordenes!$T$2:$T$840,"Válida",Ordenes!$F$2:$F$840,IF($B$4="Todos","*",$B$4),Ordenes!$G$2:$G$840,IF($B$5="Todos","*",$B$5)) | E22: =SUMIFS(Ordenes!$P$2:$P$840,Ordenes!$D$2:$D$840,$B22,Ordenes!$E$2:$E$840,$C22,Ordenes!$T$2:$T$840,"Válida",Ordenes!$F$2:$F$840,IF($B$4="Todos","*",$B$4),Ordenes!$G$2:$G$840,IF($B$5="Todos","*",$B$5)) | F22: =SUMIFS(Ordenes!$Q$2:$Q$840,Ordenes!$D$2:$D$840,$B22,Ordenes!$E$2:$E$840,$C22,Ordenes!$T$2:$T$840,"Válida",Ordenes!$F$2:$F$840,IF($B$4="Todos","*",$B$4),Ordenes!$G$2:$G$840,IF($B$5="Todos","*",$B$5)) | G22: =IF(F22=0,NA(),E22/F22) | H22: =IFERROR(SUMIFS(Ordenes!$V$2:$V$840,Ordenes!$D$2:$D$840,$B22,Ordenes!$E$2:$E$840,$C22,Ordenes!$T$2:$T$840,"Válida",Ordenes!$F$2:$F$840,IF($B$4="Todos","*",$B$4),Ordenes!$G$2:$G$840,IF($B$5="Todos","*",$B$5))/F22,NA()) | I22: =IFERROR((G22-H22)*100,"") | J22: =IFERROR(ABS(G22-G21),"") | K22: =$G$7 | L22: =$G$10 | M22: =$G$11 | N22: =IF(ISNA(G22),"Sin producción",IF(L22="","Sin límites",IF(G22>L22,"▲ Sobre LCS",IF(G22<M22,"▼ Bajo LCI","En control")))) | O22: =COUNTIFS(Ordenes!$D$2:$D$840,$B22,Ordenes!$E$2:$E$840,$C22,Ordenes!$T$2:$T$840,"A corregir",Ordenes!$F$2:$F$840,IF($B$4="Todos","*",$B$4),Ordenes!$G$2:$G$840,IF($B$5="Todos","*",$B$5))
A23: Ago 2026 | B23: 2026 | C23: 8 | D23: =COUNTIFS(Ordenes!$D$2:$D$840,$B23,Ordenes!$E$2:$E$840,$C23,Ordenes!$T$2:$T$840,"Válida",Ordenes!$F$2:$F$840,IF($B$4="Todos","*",$B$4),Ordenes!$G$2:$G$840,IF($B$5="Todos","*",$B$5)) | E23: =SUMIFS(Ordenes!$P$2:$P$840,Ordenes!$D$2:$D$840,$B23,Ordenes!$E$2:$E$840,$C23,Ordenes!$T$2:$T$840,"Válida",Ordenes!$F$2:$F$840,IF($B$4="Todos","*",$B$4),Ordenes!$G$2:$G$840,IF($B$5="Todos","*",$B$5)) | F23: =SUMIFS(Ordenes!$Q$2:$Q$840,Ordenes!$D$2:$D$840,$B23,Ordenes!$E$2:$E$840,$C23,Ordenes!$T$2:$T$840,"Válida",Ordenes!$F$2:$F$840,IF($B$4="Todos","*",$B$4),Ordenes!$G$2:$G$840,IF($B$5="Todos","*",$B$5)) | G23: =IF(F23=0,NA(),E23/F23) | H23: =IFERROR(SUMIFS(Ordenes!$V$2:$V$840,Ordenes!$D$2:$D$840,$B23,Ordenes!$E$2:$E$840,$C23,Ordenes!$T$2:$T$840,"Válida",Ordenes!$F$2:$F$840,IF($B$4="Todos","*",$B$4),Ordenes!$G$2:$G$840,IF($B$5="Todos","*",$B$5))/F23,NA()) | I23: =IFERROR((G23-H23)*100,"") | J23: =IFERROR(ABS(G23-G22),"") | K23: =$G$7 | L23: =$G$10 | M23: =$G$11 | N23: =IF(ISNA(G23),"Sin producción",IF(L23="","Sin límites",IF(G23>L23,"▲ Sobre LCS",IF(G23<M23,"▼ Bajo LCI","En control")))) | O23: =COUNTIFS(Ordenes!$D$2:$D$840,$B23,Ordenes!$E$2:$E$840,$C23,Ordenes!$T$2:$T$840,"A corregir",Ordenes!$F$2:$F$840,IF($B$4="Todos","*",$B$4),Ordenes!$G$2:$G$840,IF($B$5="Todos","*",$B$5))
A24: Sep 2026 | B24: 2026 | C24: 9 | D24: =COUNTIFS(Ordenes!$D$2:$D$840,$B24,Ordenes!$E$2:$E$840,$C24,Ordenes!$T$2:$T$840,"Válida",Ordenes!$F$2:$F$840,IF($B$4="Todos","*",$B$4),Ordenes!$G$2:$G$840,IF($B$5="Todos","*",$B$5)) | E24: =SUMIFS(Ordenes!$P$2:$P$840,Ordenes!$D$2:$D$840,$B24,Ordenes!$E$2:$E$840,$C24,Ordenes!$T$2:$T$840,"Válida",Ordenes!$F$2:$F$840,IF($B$4="Todos","*",$B$4),Ordenes!$G$2:$G$840,IF($B$5="Todos","*",$B$5)) | F24: =SUMIFS(Ordenes!$Q$2:$Q$840,Ordenes!$D$2:$D$840,$B24,Ordenes!$E$2:$E$840,$C24,Ordenes!$T$2:$T$840,"Válida",Ordenes!$F$2:$F$840,IF($B$4="Todos","*",$B$4),Ordenes!$G$2:$G$840,IF($B$5="Todos","*",$B$5)) | G24: =IF(F24=0,NA(),E24/F24) | H24: =IFERROR(SUMIFS(Ordenes!$V$2:$V$840,Ordenes!$D$2:$D$840,$B24,Ordenes!$E$2:$E$840,$C24,Ordenes!$T$2:$T$840,"Válida",Ordenes!$F$2:$F$840,IF($B$4="Todos","*",$B$4),Ordenes!$G$2:$G$840,IF($B$5="Todos","*",$B$5))/F24,NA()) | I24: =IFERROR((G24-H24)*100,"") | J24: =IFERROR(ABS(G24-G23),"") | K24: =$G$7 | L24: =$G$10 | M24: =$G$11 | N24: =IF(ISNA(G24),"Sin producción",IF(L24="","Sin límites",IF(G24>L24,"▲ Sobre LCS",IF(G24<M24,"▼ Bajo LCI","En control")))) | O24: =COUNTIFS(Ordenes!$D$2:$D$840,$B24,Ordenes!$E$2:$E$840,$C24,Ordenes!$T$2:$T$840,"A corregir",Ordenes!$F$2:$F$840,IF($B$4="Todos","*",$B$4),Ordenes!$G$2:$G$840,IF($B$5="Todos","*",$B$5))

Sheet Carta semanal
A1: Carta de control semanal
A2: Carta I-MR sobre el rendimiento ponderado (Σ kg producidos / Σ kg consumidos) de las órdenes válidas (≤ 100 %).
A4: Grupo: | B4: Todos | C4: ← elige un grupo de la lista (celda amarilla) o deja «Todos»
A5: Producto: | B5: Todos | C5: ← escribe el nombre exacto del producto (columna Producto de «Ordenes») o deja «Todos»
F7: LC (rend. ponderado) | G7: =IFERROR(SUM(E16:E53)/SUM(F16:F53),"") | H7: d2 = 1,128 es la constante de la carta I-MR para rangos móviles de 2 puntos.
F8: MR̄ (promedio rango móvil) | G8: =IFERROR(AVERAGE(J16:J53),"")
F9: σ = MR̄ / 1,128 | G9: =IFERROR(G8/1.128,"")
F10: LCS = LC + 3σ | G10: =IFERROR(G7+3*G9,"")
F11: LCI = LC − 3σ | G11: =IFERROR(G7-3*G9,"")
F12: Meta ponderada | G12: =IFERROR(SUMIFS(Ordenes!$V$2:$V$840,Ordenes!$T$2:$T$840,"Válida",Ordenes!$F$2:$F$840,IF($B$4="Todos","*",$B$4),Ordenes!$G$2:$G$840,IF($B$5="Todos","*",$B$5))/SUMIFS(Ordenes!$Q$2:$Q$840,Ordenes!$T$2:$T$840,"Válida",Ordenes!$F$2:$F$840,IF($B$4="Todos","*",$B$4),Ordenes!$G$2:$G$840,IF($B$5="Todos","*",$B$5)),"")
A15: Período | B15: Año ISO | C15: Semana | D15: Órdenes válidas | E15: Kg producidos | F15: Kg consumidos | G15: Rend. met. | H15: Meta | I15: vs meta (pp) | J15: MR | K15: LC | L15: LCS | M15: LCI | N15: Estado | O15: Órdenes a corregir
A16: S01 2026 (29 dic) | B16: 2026 | C16: 1 | D16: =COUNTIFS(Ordenes!$W$2:$W$840,$B16,Ordenes!$X$2:$X$840,$C16,Ordenes!$T$2:$T$840,"Válida",Ordenes!$F$2:$F$840,IF($B$4="Todos","*",$B$4),Ordenes!$G$2:$G$840,IF($B$5="Todos","*",$B$5)) | E16: =SUMIFS(Ordenes!$P$2:$P$840,Ordenes!$W$2:$W$840,$B16,Ordenes!$X$2:$X$840,$C16,Ordenes!$T$2:$T$840,"Válida",Ordenes!$F$2:$F$840,IF($B$4="Todos","*",$B$4),Ordenes!$G$2:$G$840,IF($B$5="Todos","*",$B$5)) | F16: =SUMIFS(Ordenes!$Q$2:$Q$840,Ordenes!$W$2:$W$840,$B16,Ordenes!$X$2:$X$840,$C16,Ordenes!$T$2:$T$840,"Válida",Ordenes!$F$2:$F$840,IF($B$4="Todos","*",$B$4),Ordenes!$G$2:$G$840,IF($B$5="Todos","*",$B$5)) | G16: =IF(F16=0,NA(),E16/F16) | H16: =IFERROR(SUMIFS(Ordenes!$V$2:$V$840,Ordenes!$W$2:$W$840,$B16,Ordenes!$X$2:$X$840,$C16,Ordenes!$T$2:$T$840,"Válida",Ordenes!$F$2:$F$840,IF($B$4="Todos","*",$B$4),Ordenes!$G$2:$G$840,IF($B$5="Todos","*",$B$5))/F16,NA()) | I16: =IFERROR((G16-H16)*100,"") | K16: =$G$7 | L16: =$G$10 | M16: =$G$11 | N16: =IF(ISNA(G16),"Sin producción",IF(L16="","Sin límites",IF(G16>L16,"▲ Sobre LCS",IF(G16<M16,"▼ Bajo LCI","En control")))) | O16: =COUNTIFS(Ordenes!$W$2:$W$840,$B16,Ordenes!$X$2:$X$840,$C16,Ordenes!$T$2:$T$840,"A corregir",Ordenes!$F$2:$F$840,IF($B$4="Todos","*",$B$4),Ordenes!$G$2:$G$840,IF($B$5="Todos","*",$B$5))
A17: S02 2026 (5 ene) | B17: 2026 | C17: 2 | D17: =COUNTIFS(Ordenes!$W$2:$W$840,$B17,Ordenes!$X$2:$X$840,$C17,Ordenes!$T$2:$T$840,"Válida",Ordenes!$F$2:$F$840,IF($B$4="Todos","*",$B$4),Ordenes!$G$2:$G$840,IF($B$5="Todos","*",$B$5)) | E17: =SUMIFS(Ordenes!$P$2:$P$840,Ordenes!$W$2:$W$840,$B17,Ordenes!$X$2:$X$840,$C17,Ordenes!$T$2:$T$840,"Válida",Ordenes!$F$2:$F$840,IF($B$4="Todos","*",$B$4),Ordenes!$G$2:$G$840,IF($B$5="Todos","*",$B$5)) | F17: =SUMIFS(Ordenes!$Q$2:$Q$840,Ordenes!$W$2:$W$840,$B17,Ordenes!$X$2:$X$840,$C17,Ordenes!$T$2:$T$840,"Válida",Ordenes!$F$2:$F$840,IF($B$4="Todos","*",$B$4),Ordenes!$G$2:$G$840,IF($B$5="Todos","*",$B$5)) | G17: =IF(F17=0,NA(),E17/F17) | H17: =IFERROR(SUMIFS(Ordenes!$V$2:$V$840,Ordenes!$W$2:$W$840,$B17,Ordenes!$X$2:$X$840,$C17,Ordenes!$T$2:$T$840,"Válida",Ordenes!$F$2:$F$840,IF($B$4="Todos","*",$B$4),Ordenes!$G$2:$G$840,IF($B$5="Todos","*",$B$5))/F17,NA()) | I17: =IFERROR((G17-H17)*100,"") | J17: =IFERROR(ABS(G17-G16),"") | K17: =$G$7 | L17: =$G$10 | M17: =$G$11 | N17: =IF(ISNA(G17),"Sin producción",IF(L17="","Sin límites",IF(G17>L17,"▲ Sobre LCS",IF(G17<M17,"▼ Bajo LCI","En control")))) | O17: =COUNTIFS(Ordenes!$W$2:$W$840,$B17,Ordenes!$X$2:$X$840,$C17,Ordenes!$T$2:$T$840,"A corregir",Ordenes!$F$2:$F$840,IF($B$4="Todos","*",$B$4),Ordenes!$G$2:$G$840,IF($B$5="Todos","*",$B$5))
A18: S03 2026 (12 ene) | B18: 2026 | C18: 3 | D18: =COUNTIFS(Ordenes!$W$2:$W$840,$B18,Ordenes!$X$2:$X$840,$C18,Ordenes!$T$2:$T$840,"Válida",Ordenes!$F$2:$F$840,IF($B$4="Todos","*",$B$4),Ordenes!$G$2:$G$840,IF($B$5="Todos","*",$B$5)) | E18: =SUMIFS(Ordenes!$P$2:$P$840,Ordenes!$W$2:$W$840,$B18,Ordenes!$X$2:$X$840,$C18,Ordenes!$T$2:$T$840,"Válida",Ordenes!$F$2:$F$840,IF($B$4="Todos","*",$B$4),Ordenes!$G$2:$G$840,IF($B$5="Todos","*",$B$5)) | F18: =SUMIFS(Ordenes!$Q$2:$Q$840,Ordenes!$W$2:$W$840,$B18,Ordenes!$X$2:$X$840,$C18,Ordenes!$T$2:$T$840,"Válida",Ordenes!$F$2:$F$840,IF($B$4="Todos","*",$B$4),Ordenes!$G$2:$G$840,IF($B$5="Todos","*",$B$5)) | G18: =IF(F18=0,NA(),E18/F18) | H18: =IFERROR(SUMIFS(Ordenes!$V$2:$V$840,Ordenes!$W$2:$W$840,$B18,Ordenes!$X$2:$X$840,$C18,Ordenes!$T$2:$T$840,"Válida",Ordenes!$F$2:$F$840,IF($B$4="Todos","*",$B$4),Ordenes!$G$2:$G$840,IF($B$5="Todos","*",$B$5))/F18,NA()) | I18: =IFERROR((G18-H18)*100,"") | J18: =IFERROR(ABS(G18-G17),"") | K18: =$G$7 | L18: =$G$10 | M18: =$G$11 | N18: =IF(ISNA(G18),"Sin producción",IF(L18="","Sin límites",IF(G18>L18,"▲ Sobre LCS",IF(G18<M18,"▼ Bajo LCI","En control")))) | O18: =COUNTIFS(Ordenes!$W$2:$W$840,$B18,Ordenes!$X$2:$X$840,$C18,Ordenes!$T$2:$T$840,"A corregir",Ordenes!$F$2:$F$840,IF($B$4="Todos","*",$B$4),Ordenes!$G$2:$G$840,IF($B$5="Todos","*",$B$5))
A19: S04 2026 (19 ene) | B19: 2026 | C19: 4 | D19: =COUNTIFS(Ordenes!$W$2:$W$840,$B19,Ordenes!$X$2:$X$840,$C19,Ordenes!$T$2:$T$840,"Válida",Ordenes!$F$2:$F$840,IF($B$4="Todos","*",$B$4),Ordenes!$G$2:$G$840,IF($B$5="Todos","*",$B$5)) | E19: =SUMIFS(Ordenes!$P$2:$P$840,Ordenes!$W$2:$W$840,$B19,Ordenes!$X$2:$X$840,$C19,Ordenes!$T$2:$T$840,"Válida",Ordenes!$F$2:$F$840,IF($B$4="Todos","*",$B$4),Ordenes!$G$2:$G$840,IF($B$5="Todos","*",$B$5)) | F19: =SUMIFS(Ordenes!$Q$2:$Q$840,Ordenes!$W$2:$W$840,$B19,Ordenes!$X$2:$X$840,$C19,Ordenes!$T$2:$T$840,"Válida",Ordenes!$F$2:$F$840,IF($B$4="Todos","*",$B$4),Ordenes!$G$2:$G$840,IF($B$5="Todos","*",$B$5)) | G19: =IF(F19=0,NA(),E19/F19) | H19: =IFERROR(SUMIFS(Ordenes!$V$2:$V$840,Ordenes!$W$2:$W$840,$B19,Ordenes!$X$2:$X$840,$C19,Ordenes!$T$2:$T$840,"Válida",Ordenes!$F$2:$F$840,IF($B$4="Todos","*",$B$4),Ordenes!$G$2:$G$840,IF($B$5="Todos","*",$B$5))/F19,NA()) | I19: =IFERROR((G19-H19)*100,"") | J19: =IFERROR(ABS(G19-G18),"") | K19: =$G$7 | L19: =$G$10 | M19: =$G$11 | N19: =IF(ISNA(G19),"Sin producción",IF(L19="","Sin límites",IF(G19>L19,"▲ Sobre LCS",IF(G19<M19,"▼ Bajo LCI","En control")))) | O19: =COUNTIFS(Ordenes!$W$2:$W$840,$B19,Ordenes!$X$2:$X$840,$C19,Ordenes!$T$2:$T$840,"A corregir",Ordenes!$F$2:$F$840,IF($B$4="Todos","*",$B$4),Ordenes!$G$2:$G$840,IF($B$5="Todos","*",$B$5))
A20: S05 2026 (26 ene) | B20: 2026 | C20: 5 | D20: =COUNTIFS(Ordenes!$W$2:$W$840,$B20,Ordenes!$X$2:$X$840,$C20,Ordenes!$T$2:$T$840,"Válida",Ordenes!$F$2:$F$840,IF($B$4="Todos","*",$B$4),Ordenes!$G$2:$G$840,IF($B$5="Todos","*",$B$5)) | E20: =SUMIFS(Ordenes!$P$2:$P$840,Ordenes!$W$2:$W$840,$B20,Ordenes!$X$2:$X$840,$C20,Ordenes!$T$2:$T$840,"Válida",Ordenes!$F$2:$F$840,IF($B$4="Todos","*",$B$4),Ordenes!$G$2:$G$840,IF($B$5="Todos","*",$B$5)) | F20: =SUMIFS(Ordenes!$Q$2:$Q$840,Ordenes!$W$2:$W$840,$B20,Ordenes!$X$2:$X$840,$C20,Ordenes!$T$2:$T$840,"Válida",Ordenes!$F$2:$F$840,IF($B$4="Todos","*",$B$4),Ordenes!$G$2:$G$840,IF($B$5="Todos","*",$B$5)) | G20: =IF(F20=0,NA(),E20/F20) | H20: =IFERROR(SUMIFS(Ordenes!$V$2:$V$840,Ordenes!$W$2:$W$840,$B20,Ordenes!$X$2:$X$840,$C20,Ordenes!$T$2:$T$840,"Válida",Ordenes!$F$2:$F$840,IF($B$4="Todos","*",$B$4),Ordenes!$G$2:$G$840,IF($B$5="Todos","*",$B$5))/F20,NA()) | I20: =IFERROR((G20-H20)*100,"") | J20: =IFERROR(ABS(G20-G19),"") | K20: =$G$7 | L20: =$G$10 | M20: =$G$11 | N20: =IF(ISNA(G20),"Sin producción",IF(L20="","Sin límites",IF(G20>L20,"▲ Sobre LCS",IF(G20<M20,"▼ Bajo LCI","En control")))) | O20: =COUNTIFS(Ordenes!$W$2:$W$840,$B20,Ordenes!$X$2:$X$840,$C20,Ordenes!$T$2:$T$840,"A corregir",Ordenes!$F$2:$F$840,IF($B$4="Todos","*",$B$4),Ordenes!$G$2:$G$840,IF($B$5="Todos","*",$B$5))
A21: S06 2026 (2 feb) | B21: 2026 | C21: 6 | D21: =COUNTIFS(Ordenes!$W$2:$W$840,$B21,Ordenes!$X$2:$X$840,$C21,Ordenes!$T$2:$T$840,"Válida",Ordenes!$F$2:$F$840,IF($B$4="Todos","*",$B$4),Ordenes!$G$2:$G$840,IF($B$5="Todos","*",$B$5)) | E21: =SUMIFS(Ordenes!$P$2:$P$840,Ordenes!$W$2:$W$840,$B21,Ordenes!$X$2:$X$840,$C21,Ordenes!$T$2:$T$840,"Válida",Ordenes!$F$2:$F$840,IF($B$4="Todos","*",$B$4),Ordenes!$G$2:$G$840,IF($B$5="Todos","*",$B$5)) | F21: =SUMIFS(Ordenes!$Q$2:$Q$840,Ordenes!$W$2:$W$840,$B21,Ordenes!$X$2:$X$840,$C21,Ordenes!$T$2:$T$840,"Válida",Ordenes!$F$2:$F$840,IF($B$4="Todos","*",$B$4),Ordenes!$G$2:$G$840,IF($B$5="Todos","*",$B$5)) | G21: =IF(F21=0,NA(),E21/F21) | H21: =IFERROR(SUMIFS(Ordenes!$V$2:$V$840,Ordenes!$W$2:$W$840,$B21,Ordenes!$X$2:$X$840,$C21,Ordenes!$T$2:$T$840,"Válida",Ordenes!$F$2:$F$840,IF($B$4="Todos","*",$B$4),Ordenes!$G$2:$G$840,IF($B$5="Todos","*",$B$5))/F21,NA()) | I21: =IFERROR((G21-H21)*100,"") | J21: =IFERROR(ABS(G21-G20),"") | K21: =$G$7 | L21: =$G$10 | M21: =$G$11 | N21: =IF(ISNA(G21),"Sin producción",IF(L21="","Sin límites",IF(G21>L21,"▲ Sobre LCS",IF(G21<M21,"▼ Bajo LCI","En control")))) | O21: =COUNTIFS(Ordenes!$W$2:$W$840,$B21,Ordenes!$X$2:$X$840,$C21,Ordenes!$T$2:$T$840,"A corregir",Ordenes!$F$2:$F$840,IF($B$4="Todos","*",$B$4),Ordenes!$G$2:$G$840,IF($B$5="Todos","*",$B$5))
A22: S07 2026 (9 feb) | B22: 2026 | C22: 7 | D22: =COUNTIFS(Ordenes!$W$2:$W$840,$B22,Ordenes!$X$2:$X$840,$C22,Ordenes!$T$2:$T$840,"Válida",Ordenes!$F$2:$F$840,IF($B$4="Todos","*",$B$4),Ordenes!$G$2:$G$840,IF($B$5="Todos","*",$B$5)) | E22: =SUMIFS(Ordenes!$P$2:$P$840,Ordenes!$W$2:$W$840,$B22,Ordenes!$X$2:$X$840,$C22,Ordenes!$T$2:$T$840,"Válida",Ordenes!$F$2:$F$840,IF($B$4="Todos","*",$B$4),Ordenes!$G$2:$G$840,IF($B$5="Todos","*",$B$5)) | F22: =SUMIFS(Ordenes!$Q$2:$Q$840,Ordenes!$W$2:$W$840,$B22,Ordenes!$X$2:$X$840,$C22,Ordenes!$T$2:$T$840,"Válida",Ordenes!$F$2:$F$840,IF($B$4="Todos","*",$B$4),Ordenes!$G$2:$G$840,IF($B$5="Todos","*",$B$5)) | G22: =IF(F22=0,NA(),E22/F22) | H22: =IFERROR(SUMIFS(Ordenes!$V$2:$V$840,Ordenes!$W$2:$W$840,$B22,Ordenes!$X$2:$X$840,$C22,Ordenes!$T$2:$T$840,"Válida",Ordenes!$F$2:$F$840,IF($B$4="Todos","*",$B$4),Ordenes!$G$2:$G$840,IF($B$5="Todos","*",$B$5))/F22,NA()) | I22: =IFERROR((G22-H22)*100,"") | J22: =IFERROR(ABS(G22-G21),"") | K22: =$G$7 | L22: =$G$10 | M22: =$G$11 | N22: =IF(ISNA(G22),"Sin producción",IF(L22="","Sin límites",IF(G22>L22,"▲ Sobre LCS",IF(G22<M22,"▼ Bajo LCI","En control")))) | O22: =COUNTIFS(Ordenes!$W$2:$W$840,$B22,Ordenes!$X$2:$X$840,$C22,Ordenes!$T$2:$T$840,"A corregir",Ordenes!$F$2:$F$840,IF($B$4="Todos","*",$B$4),Ordenes!$G$2:$G$840,IF($B$5="Todos","*",$B$5))
A23: S08 2026 (16 feb) | B23: 2026 | C23: 8 | D23: =COUNTIFS(Ordenes!$W$2:$W$840,$B23,Ordenes!$X$2:$X$840,$C23,Ordenes!$T$2:$T$840,"Válida",Ordenes!$F$2:$F$840,IF($B$4="Todos","*",$B$4),Ordenes!$G$2:$G$840,IF($B$5="Todos","*",$B$5)) | E23: =SUMIFS(Ordenes!$P$2:$P$840,Ordenes!$W$2:$W$840,$B23,Ordenes!$X$2:$X$840,$C23,Ordenes!$T$2:$T$840,"Válida",Ordenes!$F$2:$F$840,IF($B$4="Todos","*",$B$4),Ordenes!$G$2:$G$840,IF($B$5="Todos","*",$B$5)) | F23: =SUMIFS(Ordenes!$Q$2:$Q$840,Ordenes!$W$2:$W$840,$B23,Ordenes!$X$2:$X$840,$C23,Ordenes!$T$2:$T$840,"Válida",Ordenes!$F$2:$F$840,IF($B$4="Todos","*",$B$4),Ordenes!$G$2:$G$840,IF($B$5="Todos","*",$B$5)) | G23: =IF(F23=0,NA(),E23/F23) | H23: =IFERROR(SUMIFS(Ordenes!$V$2:$V$840,Ordenes!$W$2:$W$840,$B23,Ordenes!$X$2:$X$840,$C23,Ordenes!$T$2:$T$840,"Válida",Ordenes!$F$2:$F$840,IF($B$4="Todos","*",$B$4),Ordenes!$G$2:$G$840,IF($B$5="Todos","*",$B$5))/F23,NA()) | I23: =IFERROR((G23-H23)*100,"") | J23: =IFERROR(ABS(G23-G22),"") | K23: =$G$7 | L23: =$G$10 | M23: =$G$11 | N23: =IF(ISNA(G23),"Sin producción",IF(L23="","Sin límites",IF(G23>L23,"▲ Sobre LCS",IF(G23<M23,"▼ Bajo LCI","En control")))) | O23: =COUNTIFS(Ordenes!$W$2:$W$840,$B23,Ordenes!$X$2:$X$840,$C23,Ordenes!$T$2:$T$840,"A corregir",Ordenes!$F$2:$F$840,IF($B$4="Todos","*",$B$4),Ordenes!$G$2:$G$840,IF($B$5="Todos","*",$B$5))
A24: S09 2026 (23 feb) | B24: 2026 | C24: 9 | D24: =COUNTIFS(Ordenes!$W$2:$W$840,$B24,Ordenes!$X$2:$X$840,$C24,Ordenes!$T$2:$T$840,"Válida",Ordenes!$F$2:$F$840,IF($B$4="Todos","*",$B$4),Ordenes!$G$2:$G$840,IF($B$5="Todos","*",$B$5)) | E24: =SUMIFS(Ordenes!$P$2:$P$840,Ordenes!$W$2:$W$840,$B24,Ordenes!$X$2:$X$840,$C24,Ordenes!$T$2:$T$840,"Válida",Ordenes!$F$2:$F$840,IF($B$4="Todos","*",$B$4),Ordenes!$G$2:$G$840,IF($B$5="Todos","*",$B$5)) | F24: =SUMIFS(Ordenes!$Q$2:$Q$840,Ordenes!$W$2:$W$840,$B24,Ordenes!$X$2:$X$840,$C24,Ordenes!$T$2:$T$840,"Válida",Ordenes!$F$2:$F$840,IF($B$4="Todos","*",$B$4),Ordenes!$G$2:$G$840,IF($B$5="Todos","*",$B$5)) | G24: =IF(F24=0,NA(),E24/F24) | H24: =IFERROR(SUMIFS(Ordenes!$V$2:$V$840,Ordenes!$W$2:$W$840,$B24,Ordenes!$X$2:$X$840,$C24,Ordenes!$T$2:$T$840,"Válida",Ordenes!$F$2:$F$840,IF($B$4="Todos","*",$B$4),Ordenes!$G$2:$G$840,IF($B$5="Todos","*",$B$5))/F24,NA()) | I24: =IFERROR((G24-H24)*100,"") | J24: =IFERROR(ABS(G24-G23),"") | K24: =$G$7 | L24: =$G$10 | M24: =$G$11 | N24: =IF(ISNA(G24),"Sin producción",IF(L24="","Sin límites",IF(G24>L24,"▲ Sobre LCS",IF(G24<M24,"▼ Bajo LCI","En control")))) | O24: =COUNTIFS(Ordenes!$W$2:$W$840,$B24,Ordenes!$X$2:$X$840,$C24,Ordenes!$T$2:$T$840,"A corregir",Ordenes!$F$2:$F$840,IF($B$4="Todos","*",$B$4),Ordenes!$G$2:$G$840,IF($B$5="Todos","*",$B$5))
A25: S10 2026 (2 mar) | B25: 2026 | C25: 10 | D25: =COUNTIFS(Ordenes!$W$2:$W$840,$B25,Ordenes!$X$2:$X$840,$C25,Ordenes!$T$2:$T$840,"Válida",Ordenes!$F$2:$F$840,IF($B$4="Todos","*",$B$4),Ordenes!$G$2:$G$840,IF($B$5="Todos","*",$B$5)) | E25: =SUMIFS(Ordenes!$P$2:$P$840,Ordenes!$W$2:$W$840,$B25,Ordenes!$X$2:$X$840,$C25,Ordenes!$T$2:$T$840,"Válida",Ordenes!$F$2:$F$840,IF($B$4="Todos","*",$B$4),Ordenes!$G$2:$G$840,IF($B$5="Todos","*",$B$5)) | F25: =SUMIFS(Ordenes!$Q$2:$Q$840,Ordenes!$W$2:$W$840,$B25,Ordenes!$X$2:$X$840,$C25,Ordenes!$T$2:$T$840,"Válida",Ordenes!$F$2:$F$840,IF($B$4="Todos","*",$B$4),Ordenes!$G$2:$G$840,IF($B$5="Todos","*",$B$5)) | G25: =IF(F25=0,NA(),E25/F25) | H25: =IFERROR(SUMIFS(Ordenes!$V$2:$V$840,Ordenes!$W$2:$W$840,$B25,Ordenes!$X$2:$X$840,$C25,Ordenes!$T$2:$T$840,"Válida",Ordenes!$F$2:$F$840,IF($B$4="Todos","*",$B$4),Ordenes!$G$2:$G$840,IF($B$5="Todos","*",$B$5))/F25,NA()) | I25: =IFERROR((G25-H25)*100,"") | J25: =IFERROR(ABS(G25-G24),"") | K25: =$G$7 | L25: =$G$10 | M25: =$G$11 | N25: =IF(ISNA(G25),"Sin producción",IF(L25="","Sin límites",IF(G25>L25,"▲ Sobre LCS",IF(G25<M25,"▼ Bajo LCI","En control")))) | O25: =COUNTIFS(Ordenes!$W$2:$W$840,$B25,Ordenes!$X$2:$X$840,$C25,Ordenes!$T$2:$T$840,"A corregir",Ordenes!$F$2:$F$840,IF($B$4="Todos","*",$B$4),Ordenes!$G$2:$G$840,IF($B$5="Todos","*",$B$5))
A26: S11 2026 (9 mar) | B26: 2026 | C26: 11 | D26: =COUNTIFS(Ordenes!$W$2:$W$840,$B26,Ordenes!$X$2:$X$840,$C26,Ordenes!$T$2:$T$840,"Válida",Ordenes!$F$2:$F$840,IF($B$4="Todos","*",$B$4),Ordenes!$G$2:$G$840,IF($B$5="Todos","*",$B$5)) | E26: =SUMIFS(Ordenes!$P$2:$P$840,Ordenes!$W$2:$W$840,$B26,Ordenes!$X$2:$X$840,$C26,Ordenes!$T$2:$T$840,"Válida",Ordenes!$F$2:$F$840,IF($B$4="Todos","*",$B$4),Ordenes!$G$2:$G$840,IF($B$5="Todos","*",$B$5)) | F26: =SUMIFS(Ordenes!$Q$2:$Q$840,Ordenes!$W$2:$W$840,$B26,Ordenes!$X$2:$X$840,$C26,Ordenes!$T$2:$T$840,"Válida",Ordenes!$F$2:$F$840,IF($B$4="Todos","*",$B$4),Ordenes!$G$2:$G$840,IF($B$5="Todos","*",$B$5)) | G26: =IF(F26=0,NA(),E26/F26) | H26: =IFERROR(SUMIFS(Ordenes!$V$2:$V$840,Ordenes!$W$2:$W$840,$B26,Ordenes!$X$2:$X$840,$C26,Ordenes!$T$2:$T$840,"Válida",Ordenes!$F$2:$F$840,IF($B$4="Todos","*",$B$4),Ordenes!$G$2:$G$840,IF($B$5="Todos","*",$B$5))/F26,NA()) | I26: =IFERROR((G26-H26)*100,"") | J26: =IFERROR(ABS(G26-G25),"") | K26: =$G$7 | L26: =$G$10 | M26: =$G$11 | N26: =IF(ISNA(G26),"Sin producción",IF(L26="","Sin límites",IF(G26>L26,"▲ Sobre LCS",IF(G26<M26,"▼ Bajo LCI","En control")))) | O26: =COUNTIFS(Ordenes!$W$2:$W$840,$B26,Ordenes!$X$2:$X$840,$C26,Ordenes!$T$2:$T$840,"A corregir",Ordenes!$F$2:$F$840,IF($B$4="Todos","*",$B$4),Ordenes!$G$2:$G$840,IF($B$5="Todos","*",$B$5))
A27: S12 2026 (16 mar) | B27: 2026 | C27: 12 | D27: =COUNTIFS(Ordenes!$W$2:$W$840,$B27,Ordenes!$X$2:$X$840,$C27,Ordenes!$T$2:$T$840,"Válida",Ordenes!$F$2:$F$840,IF($B$4="Todos","*",$B$4),Ordenes!$G$2:$G$840,IF($B$5="Todos","*",$B$5)) | E27: =SUMIFS(Ordenes!$P$2:$P$840,Ordenes!$W$2:$W$840,$B27,Ordenes!$X$2:$X$840,$C27,Ordenes!$T$2:$T$840,"Válida",Ordenes!$F$2:$F$840,IF($B$4="Todos","*",$B$4),Ordenes!$G$2:$G$840,IF($B$5="Todos","*",$B$5)) | F27: =SUMIFS(Ordenes!$Q$2:$Q$840,Ordenes!$W$2:$W$840,$B27,Ordenes!$X$2:$X$840,$C27,Ordenes!$T$2:$T$840,"Válida",Ordenes!$F$2:$F$840,IF($B$4="Todos","*",$B$4),Ordenes!$G$2:$G$840,IF($B$5="Todos","*",$B$5)) | G27: =IF(F27=0,NA(),E27/F27) | H27: =IFERROR(SUMIFS(Ordenes!$V$2:$V$840,Ordenes!$W$2:$W$840,$B27,Ordenes!$X$2:$X$840,$C27,Ordenes!$T$2:$T$840,"Válida",Ordenes!$F$2:$F$840,IF($B$4="Todos","*",$B$4),Ordenes!$G$2:$G$840,IF($B$5="Todos","*",$B$5))/F27,NA()) | I27: =IFERROR((G27-H27)*100,"") | J27: =IFERROR(ABS(G27-G26),"") | K27: =$G$7 | L27: =$G$10 | M27: =$G$11 | N27: =IF(ISNA(G27),"Sin producción",IF(L27="","Sin límites",IF(G27>L27,"▲ Sobre LCS",IF(G27<M27,"▼ Bajo LCI","En control")))) | O27: =COUNTIFS(Ordenes!$W$2:$W$840,$B27,Ordenes!$X$2:$X$840,$C27,Ordenes!$T$2:$T$840,"A corregir",Ordenes!$F$2:$F$840,IF($B$4="Todos","*",$B$4),Ordenes!$G$2:$G$840,IF($B$5="Todos","*",$B$5))
A28: S13 2026 (23 mar) | B28: 2026 | C28: 13 | D28: =COUNTIFS(Ordenes!$W$2:$W$840,$B28,Ordenes!$X$2:$X$840,$C28,Ordenes!$T$2:$T$840,"Válida",Ordenes!$F$2:$F$840,IF($B$4="Todos","*",$B$4),Ordenes!$G$2:$G$840,IF($B$5="Todos","*",$B$5)) | E28: =SUMIFS(Ordenes!$P$2:$P$840,Ordenes!$W$2:$W$840,$B28,Ordenes!$X$2:$X$840,$C28,Ordenes!$T$2:$T$840,"Válida",Ordenes!$F$2:$F$840,IF($B$4="Todos","*",$B$4),Ordenes!$G$2:$G$840,IF($B$5="Todos","*",$B$5)) | F28: =SUMIFS(Ordenes!$Q$2:$Q$840,Ordenes!$W$2:$W$840,$B28,Ordenes!$X$2:$X$840,$C28,Ordenes!$T$2:$T$840,"Válida",Ordenes!$F$2:$F$840,IF($B$4="Todos","*",$B$4),Ordenes!$G$2:$G$840,IF($B$5="Todos","*",$B$5)) | G28: =IF(F28=0,NA(),E28/F28) | H28: =IFERROR(SUMIFS(Ordenes!$V$2:$V$840,Ordenes!$W$2:$W$840,$B28,Ordenes!$X$2:$X$840,$C28,Ordenes!$T$2:$T$840,"Válida",Ordenes!$F$2:$F$840,IF($B$4="Todos","*",$B$4),Ordenes!$G$2:$G$840,IF($B$5="Todos","*",$B$5))/F28,NA()) | I28: =IFERROR((G28-H28)*100,"") | J28: =IFERROR(ABS(G28-G27),"") | K28: =$G$7 | L28: =$G$10 | M28: =$G$11 | N28: =IF(ISNA(G28),"Sin producción",IF(L28="","Sin límites",IF(G28>L28,"▲ Sobre LCS",IF(G28<M28,"▼ Bajo LCI","En control")))) | O28: =COUNTIFS(Ordenes!$W$2:$W$840,$B28,Ordenes!$X$2:$X$840,$C28,Ordenes!$T$2:$T$840,"A corregir",Ordenes!$F$2:$F$840,IF($B$4="Todos","*",$B$4),Ordenes!$G$2:$G$840,IF($B$5="Todos","*",$B$5))
... A53: S39 2026 (21 sep) | B53: 2026 | C53: 39 | D53: =COUNTIFS(Ordenes!$W$2:$W$840,$B53,Ordenes!$X$2:$X$840,$C53,Ordenes!$T$2:$T$840,"Válida",Ordenes!$F$2:$F$840,IF($B$4="Todos","*",$B$4),Ordenes!$G$2:$G$840,IF($B$5="Todos","*",$B$5)) | E53: =SUMIFS(Ordenes!$P$2:$P$840,Ordenes!$W$2:$W$840,$B53,Ordenes!$X$2:$X$840,$C53,Ordenes!$T$2:$T$840,"Válida",Ordenes!$F$2:$F$840,IF($B$4="Todos","*",$B$4),Ordenes!$G$2:$G$840,IF($B$5="Todos","*",$B$5)) | F53: =SUMIFS(Ordenes!$Q$2:$Q$840,Ordenes!$W$2:$W$840,$B53,Ordenes!$X$2:$X$840,$C53,Ordenes!$T$2:$T$840,"Válida",Ordenes!$F$2:$F$840,IF($B$4="Todos","*",$B$4),Ordenes!$G$2:$G$840,IF($B$5="Todos","*",$B$5)) | G53: =IF(F53=0,NA(),E53/F53) | H53: =IFERROR(SUMIFS(Ordenes!$V$2:$V$840,Ordenes!$W$2:$W$840,$B53,Ordenes!$X$2:$X$840,$C53,Ordenes!$T$2:$T$840,"Válida",Ordenes!$F$2:$F$840,IF($B$4="Todos","*",$B$4),Ordenes!$G$2:$G$840,IF($B$5="Todos","*",$B$5))/F53,NA()) | I53: =IFERROR((G53-H53)*100,"") | J53: =IFERROR(ABS(G53-G52),"") | K53: =$G$7 | L53: =$G$10 | M53: =$G$11 | N53: =IF(ISNA(G53),"Sin producción",IF(L53="","Sin límites",IF(G53>L53,"▲ Sobre LCS",IF(G53<M53,"▼ Bajo LCI","En control")))) | O53: =COUNTIFS(Ordenes!$W$2:$W$840,$B53,Ordenes!$X$2:$X$840,$C53,Ordenes!$T$2:$T$840,"A corregir",Ordenes!$F$2:$F$840,IF($B$4="Todos","*",$B$4),Ordenes!$G$2:$G$840,IF($B$5="Todos","*",$B$5))

Sheet Carta diaria
A1: Carta de control diaria
A2: Carta I-MR sobre el rendimiento ponderado (Σ kg producidos / Σ kg consumidos) de las órdenes válidas (≤ 100 %).
A4: Grupo: | B4: Todos | C4: ← elige un grupo de la lista (celda amarilla) o deja «Todos»
A5: Producto: | B5: Todos | C5: ← escribe el nombre exacto del producto (columna Producto de «Ordenes») o deja «Todos»
F7: LC (rend. ponderado) | G7: =IFERROR(SUM(E16:E232)/SUM(F16:F232),"") | H7: d2 = 1,128 es la constante de la carta I-MR para rangos móviles de 2 puntos.
F8: MR̄ (promedio rango móvil) | G8: =IFERROR(AVERAGE(J16:J232),"")
F9: σ = MR̄ / 1,128 | G9: =IFERROR(G8/1.128,"")
F10: LCS = LC + 3σ | G10: =IFERROR(G7+3*G9,"")
F11: LCI = LC − 3σ | G11: =IFERROR(G7-3*G9,"")
F12: Meta ponderada | G12: =IFERROR(SUMIFS(Ordenes!$V$2:$V$840,Ordenes!$T$2:$T$840,"Válida",Ordenes!$F$2:$F$840,IF($B$4="Todos","*",$B$4),Ordenes!$G$2:$G$840,IF($B$5="Todos","*",$B$5))/SUMIFS(Ordenes!$Q$2:$Q$840,Ordenes!$T$2:$T$840,"Válida",Ordenes!$F$2:$F$840,IF($B$4="Todos","*",$B$4),Ordenes!$G$2:$G$840,IF($B$5="Todos","*",$B$5)),"")
A15: Período | B15: Año | C15: Mes | D15: Órdenes válidas | E15: Kg producidos | F15: Kg consumidos | G15: Rend. met. | H15: Meta | I15: vs meta (pp) | J15: MR | K15: LC | L15: LCS | M15: LCI | N15: Estado | O15: Órdenes a corregir
A16: 46024 | B16: =YEAR(A16) | C16: =MONTH(A16) | D16: =COUNTIFS(Ordenes!$C$2:$C$840,$A16,Ordenes!$T$2:$T$840,"Válida",Ordenes!$F$2:$F$840,IF($B$4="Todos","*",$B$4),Ordenes!$G$2:$G$840,IF($B$5="Todos","*",$B$5)) | E16: =SUMIFS(Ordenes!$P$2:$P$840,Ordenes!$C$2:$C$840,$A16,Ordenes!$T$2:$T$840,"Válida",Ordenes!$F$2:$F$840,IF($B$4="Todos","*",$B$4),Ordenes!$G$2:$G$840,IF($B$5="Todos","*",$B$5)) | F16: =SUMIFS(Ordenes!$Q$2:$Q$840,Ordenes!$C$2:$C$840,$A16,Ordenes!$T$2:$T$840,"Válida",Ordenes!$F$2:$F$840,IF($B$4="Todos","*",$B$4),Ordenes!$G$2:$G$840,IF($B$5="Todos","*",$B$5)) | G16: =IF(F16=0,NA(),E16/F16) | H16: =IFERROR(SUMIFS(Ordenes!$V$2:$V$840,Ordenes!$C$2:$C$840,$A16,Ordenes!$T$2:$T$840,"Válida",Ordenes!$F$2:$F$840,IF($B$4="Todos","*",$B$4),Ordenes!$G$2:$G$840,IF($B$5="Todos","*",$B$5))/F16,NA()) | I16: =IFERROR((G16-H16)*100,"") | K16: =$G$7 | L16: =$G$10 | M16: =$G$11 | N16: =IF(ISNA(G16),"Sin producción",IF(L16="","Sin límites",IF(G16>L16,"▲ Sobre LCS",IF(G16<M16,"▼ Bajo LCI","En control")))) | O16: =COUNTIFS(Ordenes!$C$2:$C$840,$A16,Ordenes!$T$2:$T$840,"A corregir",Ordenes!$F$2:$F$840,IF($B$4="Todos","*",$B$4),Ordenes!$G$2:$G$840,IF($B$5="Todos","*",$B$5))
A17: 46025 | B17: =YEAR(A17) | C17: =MONTH(A17) | D17: =COUNTIFS(Ordenes!$C$2:$C$840,$A17,Ordenes!$T$2:$T$840,"Válida",Ordenes!$F$2:$F$840,IF($B$4="Todos","*",$B$4),Ordenes!$G$2:$G$840,IF($B$5="Todos","*",$B$5)) | E17: =SUMIFS(Ordenes!$P$2:$P$840,Ordenes!$C$2:$C$840,$A17,Ordenes!$T$2:$T$840,"Válida",Ordenes!$F$2:$F$840,IF($B$4="Todos","*",$B$4),Ordenes!$G$2:$G$840,IF($B$5="Todos","*",$B$5)) | F17: =SUMIFS(Ordenes!$Q$2:$Q$840,Ordenes!$C$2:$C$840,$A17,Ordenes!$T$2:$T$840,"Válida",Ordenes!$F$2:$F$840,IF($B$4="Todos","*",$B$4),Ordenes!$G$2:$G$840,IF($B$5="Todos","*",$B$5)) | G17: =IF(F17=0,NA(),E17/F17) | H17: =IFERROR(SUMIFS(Ordenes!$V$2:$V$840,Ordenes!$C$2:$C$840,$A17,Ordenes!$T$2:$T$840,"Válida",Ordenes!$F$2:$F$840,IF($B$4="Todos","*",$B$4),Ordenes!$G$2:$G$840,IF($B$5="Todos","*",$B$5))/F17,NA()) | I17: =IFERROR((G17-H17)*100,"") | J17: =IFERROR(ABS(G17-G16),"") | K17: =$G$7 | L17: =$G$10 | M17: =$G$11 | N17: =IF(ISNA(G17),"Sin producción",IF(L17="","Sin límites",IF(G17>L17,"▲ Sobre LCS",IF(G17<M17,"▼ Bajo LCI","En control")))) | O17: =COUNTIFS(Ordenes!$C$2:$C$840,$A17,Ordenes!$T$2:$T$840,"A corregir",Ordenes!$F$2:$F$840,IF($B$4="Todos","*",$B$4),Ordenes!$G$2:$G$840,IF($B$5="Todos","*",$B$5))
A18: 46027 | B18: =YEAR(A18) | C18: =MONTH(A18) | D18: =COUNTIFS(Ordenes!$C$2:$C$840,$A18,Ordenes!$T$2:$T$840,"Válida",Ordenes!$F$2:$F$840,IF($B$4="Todos","*",$B$4),Ordenes!$G$2:$G$840,IF($B$5="Todos","*",$B$5)) | E18: =SUMIFS(Ordenes!$P$2:$P$840,Ordenes!$C$2:$C$840,$A18,Ordenes!$T$2:$T$840,"Válida",Ordenes!$F$2:$F$840,IF($B$4="Todos","*",$B$4),Ordenes!$G$2:$G$840,IF($B$5="Todos","*",$B$5)) | F18: =SUMIFS(Ordenes!$Q$2:$Q$840,Ordenes!$C$2:$C$840,$A18,Ordenes!$T$2:$T$840,"Válida",Ordenes!$F$2:$F$840,IF($B$4="Todos","*",$B$4),Ordenes!$G$2:$G$840,IF($B$5="Todos","*",$B$5)) | G18: =IF(F18=0,NA(),E18/F18) | H18: =IFERROR(SUMIFS(Ordenes!$V$2:$V$840,Ordenes!$C$2:$C$840,$A18,Ordenes!$T$2:$T$840,"Válida",Ordenes!$F$2:$F$840,IF($B$4="Todos","*",$B$4),Ordenes!$G$2:$G$840,IF($B$5="Todos","*",$B$5))/F18,NA()) | I18: =IFERROR((G18-H18)*100,"") | J18: =IFERROR(ABS(G18-G17),"") | K18: =$G$7 | L18: =$G$10 | M18: =$G$11 | N18: =IF(ISNA(G18),"Sin producción",IF(L18="","Sin límites",IF(G18>L18,"▲ Sobre LCS",IF(G18<M18,"▼ Bajo LCI","En control")))) | O18: =COUNTIFS(Ordenes!$C$2:$C$840,$A18,Ordenes!$T$2:$T$840,"A corregir",Ordenes!$F$2:$F$840,IF($B$4="Todos","*",$B$4),Ordenes!$G$2:$G$840,IF($B$5="Todos","*",$B$5))
A19: 46028 | B19: =YEAR(A19) | C19: =MONTH(A19) | D19: =COUNTIFS(Ordenes!$C$2:$C$840,$A19,Ordenes!$T$2:$T$840,"Válida",Ordenes!$F$2:$F$840,IF($B$4="Todos","*",$B$4),Ordenes!$G$2:$G$840,IF($B$5="Todos","*",$B$5)) | E19: =SUMIFS(Ordenes!$P$2:$P$840,Ordenes!$C$2:$C$840,$A19,Ordenes!$T$2:$T$840,"Válida",Ordenes!$F$2:$F$840,IF($B$4="Todos","*",$B$4),Ordenes!$G$2:$G$840,IF($B$5="Todos","*",$B$5)) | F19: =SUMIFS(Ordenes!$Q$2:$Q$840,Ordenes!$C$2:$C$840,$A19,Ordenes!$T$2:$T$840,"Válida",Ordenes!$F$2:$F$840,IF($B$4="Todos","*",$B$4),Ordenes!$G$2:$G$840,IF($B$5="Todos","*",$B$5)) | G19: =IF(F19=0,NA(),E19/F19) | H19: =IFERROR(SUMIFS(Ordenes!$V$2:$V$840,Ordenes!$C$2:$C$840,$A19,Ordenes!$T$2:$T$840,"Válida",Ordenes!$F$2:$F$840,IF($B$4="Todos","*",$B$4),Ordenes!$G$2:$G$840,IF($B$5="Todos","*",$B$5))/F19,NA()) | I19: =IFERROR((G19-H19)*100,"") | J19: =IFERROR(ABS(G19-G18),"") | K19: =$G$7 | L19: =$G$10 | M19: =$G$11 | N19: =IF(ISNA(G19),"Sin producción",IF(L19="","Sin límites",IF(G19>L19,"▲ Sobre LCS",IF(G19<M19,"▼ Bajo LCI","En control")))) | O19: =COUNTIFS(Ordenes!$C$2:$C$840,$A19,Ordenes!$T$2:$T$840,"A corregir",Ordenes!$F$2:$F$840,IF($B$4="Todos","*",$B$4),Ordenes!$G$2:$G$840,IF($B$5="Todos","*",$B$5))
A20: 46029 | B20: =YEAR(A20) | C20: =MONTH(A20) | D20: =COUNTIFS(Ordenes!$C$2:$C$840,$A20,Ordenes!$T$2:$T$840,"Válida",Ordenes!$F$2:$F$840,IF($B$4="Todos","*",$B$4),Ordenes!$G$2:$G$840,IF($B$5="Todos","*",$B$5)) | E20: =SUMIFS(Ordenes!$P$2:$P$840,Ordenes!$C$2:$C$840,$A20,Ordenes!$T$2:$T$840,"Válida",Ordenes!$F$2:$F$840,IF($B$4="Todos","*",$B$4),Ordenes!$G$2:$G$840,IF($B$5="Todos","*",$B$5)) | F20: =SUMIFS(Ordenes!$Q$2:$Q$840,Ordenes!$C$2:$C$840,$A20,Ordenes!$T$2:$T$840,"Válida",Ordenes!$F$2:$F$840,IF($B$4="Todos","*",$B$4),Ordenes!$G$2:$G$840,IF($B$5="Todos","*",$B$5)) | G20: =IF(F20=0,NA(),E20/F20) | H20: =IFERROR(SUMIFS(Ordenes!$V$2:$V$840,Ordenes!$C$2:$C$840,$A20,Ordenes!$T$2:$T$840,"Válida",Ordenes!$F$2:$F$840,IF($B$4="Todos","*",$B$4),Ordenes!$G$2:$G$840,IF($B$5="Todos","*",$B$5))/F20,NA()) | I20: =IFERROR((G20-H20)*100,"") | J20: =IFERROR(ABS(G20-G19),"") | K20: =$G$7 | L20: =$G$10 | M20: =$G$11 | N20: =IF(ISNA(G20),"Sin producción",IF(L20="","Sin límites",IF(G20>L20,"▲ Sobre LCS",IF(G20<M20,"▼ Bajo LCI","En control")))) | O20: =COUNTIFS(Ordenes!$C$2:$C$840,$A20,Ordenes!$T$2:$T$840,"A corregir",Ordenes!$F$2:$F$840,IF($B$4="Todos","*",$B$4),Ordenes!$G$2:$G$840,IF($B$5="Todos","*",$B$5))
