Workbook

Sheet Inicio
A1: Control de rendimiento metálico — plantilla
A3: Indicadores del año (Parámetros!B4)
A4: Rendimiento metálico | B4: ='Resumen mensual'!E18
A5: Meta ponderada | B5: ='Resumen mensual'!F18
A6: Brecha | B6: ='Resumen mensual'!G18
A7: Kg faltantes vs meta | B7: ='Resumen mensual'!H18 -> 0
A8: Pérdidas SAP (kg) | B8: ='Resumen mensual'!S18 -> 0
A9: Delta no explicado (kg) | B9: ='Resumen mensual'!T18 -> 0
A10: Delta / consumo | B10: ='Resumen mensual'!U18
A11: Órdenes registradas | B11: ='Resumen mensual'!B18 -> 0
A12: Órdenes bajo meta | B12: ='Resumen mensual'!I18 -> 0
A13: Órdenes con error o balance a revisar | B13: =COUNTIF(Registro!$AJ$6:$AJ$1005,"Error*")+COUNTIF(Registro!$AJ$6:$AJ$1005,"Revisar balance") -> 0
A14: Acciones abiertas con atraso | B14: =COUNTIF('Plan de acción'!R5:R204,">0") -> 0
A17: Cómo usar
A18: 1. Parámetros: fije el año, la meta general, las metas por grupo, el % de oxidación y la tolerancia del delta.
A19: 2. Registro: ingrese una fila por orden al cierre de cada turno o campaña (celdas amarillas). La fila 6 es un ejemplo: reemplácela.
A20: 3. Revise la columna Estado: 'Error', 'Revisar balance' y 'Falta registrar pérdidas' son problemas de dato; 'Bajo meta' es un problema de proceso y debe llevar Hecho, Causa y Acción.
A21: 4. Resumen mensual, Carta semanal y Pareto se actualizan solos.
A22: 5. Semanalmente: lea la carta, tome los ítems 'Prioridad (80 %)' del Pareto y abra acciones en Plan de acción.
A23: 6. Cierre cada acción comparando el rendimiento antes/después del mismo producto (columna Mejora).
A25: Leyenda
A26: Ejemplo | B26: Dato a ingresar (texto azul, fondo amarillo)
A27: Ejemplo | B27: Encabezado de columna calculada: no escribir
A28: Ejemplo | B28: Texto verde: valor traído de otra hoja
A29: Ejemplo | B29: Bajo meta / fuera de control / atrasada
A30: Ejemplo | B30: Dato a revisar (balance, tendencia)
A31: Ejemplo | B31: Cumple
A33: Hojas
A34: Registro | B34: Base por orden: producción, consumo, pérdidas por etapa, balance y análisis.
A35: Resumen mensual | B35: Rendimiento, meta, kg faltantes y pérdidas por tipo por mes; rendimiento grupo × mes.
A36: Carta semanal | B36: Carta I-MR con LC, LSC, LIC, meta y señales de fuera de control o tendencia.
A37: Pareto | B37: Pérdidas por tipo, kg faltantes por causa y por grupo, con el 80 % prioritario.
A38: Plan de acción | B38: Seguimiento de acciones, atraso y verificación de eficacia.
A39: Guía de control | B39: Qué medir, cómo leer los indicadores y rutina de control.
A40: Parámetros | B40: Metas, supuestos y listas desplegables.

Sheet Registro
A1: Registro de rendimiento metálico por orden
A2: Una fila por orden de laminación. Amarillo = dato a ingresar; gris = fórmula (no editar). Pérdidas en kg. La fila 6 es un ejemplo (orden 1008027, noviembre 2010): reemplácela.
A3: Balance: Pérdidas SAP = Consumo − Producción. Delta = Pérdidas SAP − Pérdidas medidas (T1…Cobles + Oxidación). Un delta grande indica pérdidas que no se están pesando o registrando.
A4: IDENTIFICACIÓN | L4: PRODUCCIÓN | T4: PÉRDIDAS MEDIDAS (kg) | AE4: BALANCE | AK4: ANÁLISIS DE LA DESVIACIÓN
A5: Fecha | B5: Año ISO | C5: Semana ISO | D5: Mes | E5: Turno | F5: Orden | G5: Código | H5: Material | I5: Grupo | J5: Largo palanquilla (m) | K5: N° palanquillas | L5: Horas | M5: Consumo (kg) | N5: Producción (kg) | O5: Rend. metálico | P5: Meta | Q5: Brecha vs meta | R5: Kg faltantes vs meta | S5: Productividad (t/h) | T5: T1 (kg) | U5: T2 (kg) | V5: T3 (kg) | W5: T4 (kg) | X5: Fuera de medida (kg) | Y5: Corto T4 (kg) | Z5: Cobles / barras perdidas (kg) | AA5: N° barras perdidas | AB5: Oxidación medida (kg) | AC5: Oxidación usada (kg) | AD5: Pérdidas medidas (kg) | AE5: Pérdidas SAP (kg) | AF5: Delta no explicado (kg) | AG5: Delta / consumo | AH5: Pérdidas (kg/t prod.) | AI5: aux: consumo × meta | AJ5: Estado | AK5: Hecho (qué pasó) | AL5: Causa (categoría) | AM5: Causa (detalle) | AN5: Acción | AO5: Responsable
A6: 40484 | B6: =IF(A6="","",YEAR(A6-WEEKDAY(A6,2)+4)) -> 2010 | C6: =IF(A6="","",WEEKNUM(A6,21)) -> 44 | D6: =IF(A6="","",DATE(YEAR(A6),MONTH(A6),1)) -> 40483 | E6: A | F6: 1008027 | G6: 3027 | H6: Plana 50x06 mm 6 m Comercial (N) | I6: Plana | J6: 3.2 | K6: 356 | L6: 8.23 | M6: 139814 | N6: 131826 | O6: =IF(OR(M6="",M6=0,N6=""),"",N6/M6) -> 0.94286695 | P6: =IF(M6="","",IFERROR(IF(INDEX(Parámetros!$B$14:$B$21,MATCH(I6,Parámetros!$A$14:$A$21,0))="",Parámetros!$B$5,INDEX(Parámetros!$B$14:$B$21,MATCH(I6,Parámetros!$A$14:$A$21,0))),Parámetros!$B$5)) -> 0.9609 | Q6: =IF(O6="","",(O6-P6)*100) -> -1.8033048 | R6: =IF(O6="","",MAX(0,M6*(P6-O6))) -> 2521.2726 | S6: =IF(OR(L6="",L6=0,N6=""),"",N6/1000/L6) -> 16.01774 | T6: 2000 | U6: 395 | V6: 0 | W6: 1140 | X6: 0 | Y6: 1730 | Z6: 390 | AA6: 1 | AC6: =IF(M6="","",IF(AB6="",M6*Parámetros!$B$6,AB6)) -> 2796.28 | AD6: =IF(M6="","",SUM(T6:Z6)+AC6) -> 8451.28 | AE6: =IF(OR(M6="",N6=""),"",M6-N6) -> 7988 | AF6: =IF(AE6="","",AE6-AD6) -> -463.28 | AG6: =IF(OR(AF6="",M6=0),"",AF6/M6) -> -0.0033135451 | AH6: =IF(OR(AE6="",N6=0),"",AE6/(N6/1000)) -> 60.595027 | AI6: =IF(O6="","",M6*P6) -> 134347.27 | AJ6: =IF(O6="","",IF(O6>1,"Error: rend > 100 %",IF(SUM(T6:Z6)=0,"Falta registrar pérdidas",IF(ABS(AG6)>Parámetros!$B$7,"Revisar balance",IF(O6<P6,"Bajo meta","OK"))))) -> Bajo meta | AK6: Cobles (trozo de coble y barra de sacrificio) | AL6: Eléctrico / instrumentación | AM6: HMD A5-A6 pierde señal | AN6: Chequear señales de fotoceldas y HMD, graficar en IBA | AO6: Jefe de turno
B7: =IF(A7="","",YEAR(A7-WEEKDAY(A7,2)+4)) | C7: =IF(A7="","",WEEKNUM(A7,21)) | D7: =IF(A7="","",DATE(YEAR(A7),MONTH(A7),1)) | O7: =IF(OR(M7="",M7=0,N7=""),"",N7/M7) | P7: =IF(M7="","",IFERROR(IF(INDEX(Parámetros!$B$14:$B$21,MATCH(I7,Parámetros!$A$14:$A$21,0))="",Parámetros!$B$5,INDEX(Parámetros!$B$14:$B$21,MATCH(I7,Parámetros!$A$14:$A$21,0))),Parámetros!$B$5)) | Q7: =IF(O7="","",(O7-P7)*100) | R7: =IF(O7="","",MAX(0,M7*(P7-O7))) | S7: =IF(OR(L7="",L7=0,N7=""),"",N7/1000/L7) | AC7: =IF(M7="","",IF(AB7="",M7*Parámetros!$B$6,AB7)) | AD7: =IF(M7="","",SUM(T7:Z7)+AC7) | AE7: =IF(OR(M7="",N7=""),"",M7-N7) | AF7: =IF(AE7="","",AE7-AD7) | AG7: =IF(OR(AF7="",M7=0),"",AF7/M7) | AH7: =IF(OR(AE7="",N7=0),"",AE7/(N7/1000)) | AI7: =IF(O7="","",M7*P7) | AJ7: =IF(O7="","",IF(O7>1,"Error: rend > 100 %",IF(SUM(T7:Z7)=0,"Falta registrar pérdidas",IF(ABS(AG7)>Parámetros!$B$7,"Revisar balance",IF(O7<P7,"Bajo meta","OK")))))
B8: =IF(A8="","",YEAR(A8-WEEKDAY(A8,2)+4)) | C8: =IF(A8="","",WEEKNUM(A8,21)) | D8: =IF(A8="","",DATE(YEAR(A8),MONTH(A8),1)) | O8: =IF(OR(M8="",M8=0,N8=""),"",N8/M8) | P8: =IF(M8="","",IFERROR(IF(INDEX(Parámetros!$B$14:$B$21,MATCH(I8,Parámetros!$A$14:$A$21,0))="",Parámetros!$B$5,INDEX(Parámetros!$B$14:$B$21,MATCH(I8,Parámetros!$A$14:$A$21,0))),Parámetros!$B$5)) | Q8: =IF(O8="","",(O8-P8)*100) | R8: =IF(O8="","",MAX(0,M8*(P8-O8))) | S8: =IF(OR(L8="",L8=0,N8=""),"",N8/1000/L8) | AC8: =IF(M8="","",IF(AB8="",M8*Parámetros!$B$6,AB8)) | AD8: =IF(M8="","",SUM(T8:Z8)+AC8) | AE8: =IF(OR(M8="",N8=""),"",M8-N8) | AF8: =IF(AE8="","",AE8-AD8) | AG8: =IF(OR(AF8="",M8=0),"",AF8/M8) | AH8: =IF(OR(AE8="",N8=0),"",AE8/(N8/1000)) | AI8: =IF(O8="","",M8*P8) | AJ8: =IF(O8="","",IF(O8>1,"Error: rend > 100 %",IF(SUM(T8:Z8)=0,"Falta registrar pérdidas",IF(ABS(AG8)>Parámetros!$B$7,"Revisar balance",IF(O8<P8,"Bajo meta","OK")))))
B9: =IF(A9="","",YEAR(A9-WEEKDAY(A9,2)+4)) | C9: =IF(A9="","",WEEKNUM(A9,21)) | D9: =IF(A9="","",DATE(YEAR(A9),MONTH(A9),1)) | O9: =IF(OR(M9="",M9=0,N9=""),"",N9/M9) | P9: =IF(M9="","",IFERROR(IF(INDEX(Parámetros!$B$14:$B$21,MATCH(I9,Parámetros!$A$14:$A$21,0))="",Parámetros!$B$5,INDEX(Parámetros!$B$14:$B$21,MATCH(I9,Parámetros!$A$14:$A$21,0))),Parámetros!$B$5)) | Q9: =IF(O9="","",(O9-P9)*100) | R9: =IF(O9="","",MAX(0,M9*(P9-O9))) | S9: =IF(OR(L9="",L9=0,N9=""),"",N9/1000/L9) | AC9: =IF(M9="","",IF(AB9="",M9*Parámetros!$B$6,AB9)) | AD9: =IF(M9="","",SUM(T9:Z9)+AC9) | AE9: =IF(OR(M9="",N9=""),"",M9-N9) | AF9: =IF(AE9="","",AE9-AD9) | AG9: =IF(OR(AF9="",M9=0),"",AF9/M9) | AH9: =IF(OR(AE9="",N9=0),"",AE9/(N9/1000)) | AI9: =IF(O9="","",M9*P9) | AJ9: =IF(O9="","",IF(O9>1,"Error: rend > 100 %",IF(SUM(T9:Z9)=0,"Falta registrar pérdidas",IF(ABS(AG9)>Parámetros!$B$7,"Revisar balance",IF(O9<P9,"Bajo meta","OK")))))
B10: =IF(A10="","",YEAR(A10-WEEKDAY(A10,2)+4)) | C10: =IF(A10="","",WEEKNUM(A10,21)) | D10: =IF(A10="","",DATE(YEAR(A10),MONTH(A10),1)) | O10: =IF(OR(M10="",M10=0,N10=""),"",N10/M10) | P10: =IF(M10="","",IFERROR(IF(INDEX(Parámetros!$B$14:$B$21,MATCH(I10,Parámetros!$A$14:$A$21,0))="",Parámetros!$B$5,INDEX(Parámetros!$B$14:$B$21,MATCH(I10,Parámetros!$A$14:$A$21,0))),Parámetros!$B$5)) | Q10: =IF(O10="","",(O10-P10)*100) | R10: =IF(O10="","",MAX(0,M10*(P10-O10))) | S10: =IF(OR(L10="",L10=0,N10=""),"",N10/1000/L10) | AC10: =IF(M10="","",IF(AB10="",M10*Parámetros!$B$6,AB10)) | AD10: =IF(M10="","",SUM(T10:Z10)+AC10) | AE10: =IF(OR(M10="",N10=""),"",M10-N10) | AF10: =IF(AE10="","",AE10-AD10) | AG10: =IF(OR(AF10="",M10=0),"",AF10/M10) | AH10: =IF(OR(AE10="",N10=0),"",AE10/(N10/1000)) | AI10: =IF(O10="","",M10*P10) | AJ10: =IF(O10="","",IF(O10>1,"Error: rend > 100 %",IF(SUM(T10:Z10)=0,"Falta registrar pérdidas",IF(ABS(AG10)>Parámetros!$B$7,"Revisar balance",IF(O10<P10,"Bajo meta","OK")))))
B11: =IF(A11="","",YEAR(A11-WEEKDAY(A11,2)+4)) | C11: =IF(A11="","",WEEKNUM(A11,21)) | D11: =IF(A11="","",DATE(YEAR(A11),MONTH(A11),1)) | O11: =IF(OR(M11="",M11=0,N11=""),"",N11/M11) | P11: =IF(M11="","",IFERROR(IF(INDEX(Parámetros!$B$14:$B$21,MATCH(I11,Parámetros!$A$14:$A$21,0))="",Parámetros!$B$5,INDEX(Parámetros!$B$14:$B$21,MATCH(I11,Parámetros!$A$14:$A$21,0))),Parámetros!$B$5)) | Q11: =IF(O11="","",(O11-P11)*100) | R11: =IF(O11="","",MAX(0,M11*(P11-O11))) | S11: =IF(OR(L11="",L11=0,N11=""),"",N11/1000/L11) | AC11: =IF(M11="","",IF(AB11="",M11*Parámetros!$B$6,AB11)) | AD11: =IF(M11="","",SUM(T11:Z11)+AC11) | AE11: =IF(OR(M11="",N11=""),"",M11-N11) | AF11: =IF(AE11="","",AE11-AD11) | AG11: =IF(OR(AF11="",M11=0),"",AF11/M11) | AH11: =IF(OR(AE11="",N11=0),"",AE11/(N11/1000)) | AI11: =IF(O11="","",M11*P11) | AJ11: =IF(O11="","",IF(O11>1,"Error: rend > 100 %",IF(SUM(T11:Z11)=0,"Falta registrar pérdidas",IF(ABS(AG11)>Parámetros!$B$7,"Revisar balance",IF(O11<P11,"Bajo meta","OK")))))
B12: =IF(A12="","",YEAR(A12-WEEKDAY(A12,2)+4)) | C12: =IF(A12="","",WEEKNUM(A12,21)) | D12: =IF(A12="","",DATE(YEAR(A12),MONTH(A12),1)) | O12: =IF(OR(M12="",M12=0,N12=""),"",N12/M12) | P12: =IF(M12="","",IFERROR(IF(INDEX(Parámetros!$B$14:$B$21,MATCH(I12,Parámetros!$A$14:$A$21,0))="",Parámetros!$B$5,INDEX(Parámetros!$B$14:$B$21,MATCH(I12,Parámetros!$A$14:$A$21,0))),Parámetros!$B$5)) | Q12: =IF(O12="","",(O12-P12)*100) | R12: =IF(O12="","",MAX(0,M12*(P12-O12))) | S12: =IF(OR(L12="",L12=0,N12=""),"",N12/1000/L12) | AC12: =IF(M12="","",IF(AB12="",M12*Parámetros!$B$6,AB12)) | AD12: =IF(M12="","",SUM(T12:Z12)+AC12) | AE12: =IF(OR(M12="",N12=""),"",M12-N12) | AF12: =IF(AE12="","",AE12-AD12) | AG12: =IF(OR(AF12="",M12=0),"",AF12/M12) | AH12: =IF(OR(AE12="",N12=0),"",AE12/(N12/1000)) | AI12: =IF(O12="","",M12*P12) | AJ12: =IF(O12="","",IF(O12>1,"Error: rend > 100 %",IF(SUM(T12:Z12)=0,"Falta registrar pérdidas",IF(ABS(AG12)>Parámetros!$B$7,"Revisar balance",IF(O12<P12,"Bajo meta","OK")))))
B13: =IF(A13="","",YEAR(A13-WEEKDAY(A13,2)+4)) | C13: =IF(A13="","",WEEKNUM(A13,21)) | D13: =IF(A13="","",DATE(YEAR(A13),MONTH(A13),1)) | O13: =IF(OR(M13="",M13=0,N13=""),"",N13/M13) | P13: =IF(M13="","",IFERROR(IF(INDEX(Parámetros!$B$14:$B$21,MATCH(I13,Parámetros!$A$14:$A$21,0))="",Parámetros!$B$5,INDEX(Parámetros!$B$14:$B$21,MATCH(I13,Parámetros!$A$14:$A$21,0))),Parámetros!$B$5)) | Q13: =IF(O13="","",(O13-P13)*100) | R13: =IF(O13="","",MAX(0,M13*(P13-O13))) | S13: =IF(OR(L13="",L13=0,N13=""),"",N13/1000/L13) | AC13: =IF(M13="","",IF(AB13="",M13*Parámetros!$B$6,AB13)) | AD13: =IF(M13="","",SUM(T13:Z13)+AC13) | AE13: =IF(OR(M13="",N13=""),"",M13-N13) | AF13: =IF(AE13="","",AE13-AD13) | AG13: =IF(OR(AF13="",M13=0),"",AF13/M13) | AH13: =IF(OR(AE13="",N13=0),"",AE13/(N13/1000)) | AI13: =IF(O13="","",M13*P13) | AJ13: =IF(O13="","",IF(O13>1,"Error: rend > 100 %",IF(SUM(T13:Z13)=0,"Falta registrar pérdidas",IF(ABS(AG13)>Parámetros!$B$7,"Revisar balance",IF(O13<P13,"Bajo meta","OK")))))
B14: =IF(A14="","",YEAR(A14-WEEKDAY(A14,2)+4)) | C14: =IF(A14="","",WEEKNUM(A14,21)) | D14: =IF(A14="","",DATE(YEAR(A14),MONTH(A14),1)) | O14: =IF(OR(M14="",M14=0,N14=""),"",N14/M14) | P14: =IF(M14="","",IFERROR(IF(INDEX(Parámetros!$B$14:$B$21,MATCH(I14,Parámetros!$A$14:$A$21,0))="",Parámetros!$B$5,INDEX(Parámetros!$B$14:$B$21,MATCH(I14,Parámetros!$A$14:$A$21,0))),Parámetros!$B$5)) | Q14: =IF(O14="","",(O14-P14)*100) | R14: =IF(O14="","",MAX(0,M14*(P14-O14))) | S14: =IF(OR(L14="",L14=0,N14=""),"",N14/1000/L14) | AC14: =IF(M14="","",IF(AB14="",M14*Parámetros!$B$6,AB14)) | AD14: =IF(M14="","",SUM(T14:Z14)+AC14) | AE14: =IF(OR(M14="",N14=""),"",M14-N14) | AF14: =IF(AE14="","",AE14-AD14) | AG14: =IF(OR(AF14="",M14=0),"",AF14/M14) | AH14: =IF(OR(AE14="",N14=0),"",AE14/(N14/1000)) | AI14: =IF(O14="","",M14*P14) | AJ14: =IF(O14="","",IF(O14>1,"Error: rend > 100 %",IF(SUM(T14:Z14)=0,"Falta registrar pérdidas",IF(ABS(AG14)>Parámetros!$B$7,"Revisar balance",IF(O14<P14,"Bajo meta","OK")))))
B15: =IF(A15="","",YEAR(A15-WEEKDAY(A15,2)+4)) | C15: =IF(A15="","",WEEKNUM(A15,21)) | D15: =IF(A15="","",DATE(YEAR(A15),MONTH(A15),1)) | O15: =IF(OR(M15="",M15=0,N15=""),"",N15/M15) | P15: =IF(M15="","",IFERROR(IF(INDEX(Parámetros!$B$14:$B$21,MATCH(I15,Parámetros!$A$14:$A$21,0))="",Parámetros!$B$5,INDEX(Parámetros!$B$14:$B$21,MATCH(I15,Parámetros!$A$14:$A$21,0))),Parámetros!$B$5)) | Q15: =IF(O15="","",(O15-P15)*100) | R15: =IF(O15="","",MAX(0,M15*(P15-O15))) | S15: =IF(OR(L15="",L15=0,N15=""),"",N15/1000/L15) | AC15: =IF(M15="","",IF(AB15="",M15*Parámetros!$B$6,AB15)) | AD15: =IF(M15="","",SUM(T15:Z15)+AC15) | AE15: =IF(OR(M15="",N15=""),"",M15-N15) | AF15: =IF(AE15="","",AE15-AD15) | AG15: =IF(OR(AF15="",M15=0),"",AF15/M15) | AH15: =IF(OR(AE15="",N15=0),"",AE15/(N15/1000)) | AI15: =IF(O15="","",M15*P15) | AJ15: =IF(O15="","",IF(O15>1,"Error: rend > 100 %",IF(SUM(T15:Z15)=0,"Falta registrar pérdidas",IF(ABS(AG15)>Parámetros!$B$7,"Revisar balance",IF(O15<P15,"Bajo meta","OK")))))
B16: =IF(A16="","",YEAR(A16-WEEKDAY(A16,2)+4)) | C16: =IF(A16="","",WEEKNUM(A16,21)) | D16: =IF(A16="","",DATE(YEAR(A16),MONTH(A16),1)) | O16: =IF(OR(M16="",M16=0,N16=""),"",N16/M16) | P16: =IF(M16="","",IFERROR(IF(INDEX(Parámetros!$B$14:$B$21,MATCH(I16,Parámetros!$A$14:$A$21,0))="",Parámetros!$B$5,INDEX(Parámetros!$B$14:$B$21,MATCH(I16,Parámetros!$A$14:$A$21,0))),Parámetros!$B$5)) | Q16: =IF(O16="","",(O16-P16)*100) | R16: =IF(O16="","",MAX(0,M16*(P16-O16))) | S16: =IF(OR(L16="",L16=0,N16=""),"",N16/1000/L16) | AC16: =IF(M16="","",IF(AB16="",M16*Parámetros!$B$6,AB16)) | AD16: =IF(M16="","",SUM(T16:Z16)+AC16) | AE16: =IF(OR(M16="",N16=""),"",M16-N16) | AF16: =IF(AE16="","",AE16-AD16) | AG16: =IF(OR(AF16="",M16=0),"",AF16/M16) | AH16: =IF(OR(AE16="",N16=0),"",AE16/(N16/1000)) | AI16: =IF(O16="","",M16*P16) | AJ16: =IF(O16="","",IF(O16>1,"Error: rend > 100 %",IF(SUM(T16:Z16)=0,"Falta registrar pérdidas",IF(ABS(AG16)>Parámetros!$B$7,"Revisar balance",IF(O16<P16,"Bajo meta","OK")))))
B17: =IF(A17="","",YEAR(A17-WEEKDAY(A17,2)+4)) | C17: =IF(A17="","",WEEKNUM(A17,21)) | D17: =IF(A17="","",DATE(YEAR(A17),MONTH(A17),1)) | O17: =IF(OR(M17="",M17=0,N17=""),"",N17/M17) | P17: =IF(M17="","",IFERROR(IF(INDEX(Parámetros!$B$14:$B$21,MATCH(I17,Parámetros!$A$14:$A$21,0))="",Parámetros!$B$5,INDEX(Parámetros!$B$14:$B$21,MATCH(I17,Parámetros!$A$14:$A$21,0))),Parámetros!$B$5)) | Q17: =IF(O17="","",(O17-P17)*100) | R17: =IF(O17="","",MAX(0,M17*(P17-O17))) | S17: =IF(OR(L17="",L17=0,N17=""),"",N17/1000/L17) | AC17: =IF(M17="","",IF(AB17="",M17*Parámetros!$B$6,AB17)) | AD17: =IF(M17="","",SUM(T17:Z17)+AC17) | AE17: =IF(OR(M17="",N17=""),"",M17-N17) | AF17: =IF(AE17="","",AE17-AD17) | AG17: =IF(OR(AF17="",M17=0),"",AF17/M17) | AH17: =IF(OR(AE17="",N17=0),"",AE17/(N17/1000)) | AI17: =IF(O17="","",M17*P17) | AJ17: =IF(O17="","",IF(O17>1,"Error: rend > 100 %",IF(SUM(T17:Z17)=0,"Falta registrar pérdidas",IF(ABS(AG17)>Parámetros!$B$7,"Revisar balance",IF(O17<P17,"Bajo meta","OK")))))
B18: =IF(A18="","",YEAR(A18-WEEKDAY(A18,2)+4)) | C18: =IF(A18="","",WEEKNUM(A18,21)) | D18: =IF(A18="","",DATE(YEAR(A18),MONTH(A18),1)) | O18: =IF(OR(M18="",M18=0,N18=""),"",N18/M18) | P18: =IF(M18="","",IFERROR(IF(INDEX(Parámetros!$B$14:$B$21,MATCH(I18,Parámetros!$A$14:$A$21,0))="",Parámetros!$B$5,INDEX(Parámetros!$B$14:$B$21,MATCH(I18,Parámetros!$A$14:$A$21,0))),Parámetros!$B$5)) | Q18: =IF(O18="","",(O18-P18)*100) | R18: =IF(O18="","",MAX(0,M18*(P18-O18))) | S18: =IF(OR(L18="",L18=0,N18=""),"",N18/1000/L18) | AC18: =IF(M18="","",IF(AB18="",M18*Parámetros!$B$6,AB18)) | AD18: =IF(M18="","",SUM(T18:Z18)+AC18) | AE18: =IF(OR(M18="",N18=""),"",M18-N18) | AF18: =IF(AE18="","",AE18-AD18) | AG18: =IF(OR(AF18="",M18=0),"",AF18/M18) | AH18: =IF(OR(AE18="",N18=0),"",AE18/(N18/1000)) | AI18: =IF(O18="","",M18*P18) | AJ18: =IF(O18="","",IF(O18>1,"Error: rend > 100 %",IF(SUM(T18:Z18)=0,"Falta registrar pérdidas",IF(ABS(AG18)>Parámetros!$B$7,"Revisar balance",IF(O18<P18,"Bajo meta","OK")))))
... B1005: =IF(A1005="","",YEAR(A1005-WEEKDAY(A1005,2)+4)) | C1005: =IF(A1005="","",WEEKNUM(A1005,21)) | D1005: =IF(A1005="","",DATE(YEAR(A1005),MONTH(A1005),1)) | O1005: =IF(OR(M1005="",M1005=0,N1005=""),"",N1005/M1005) | P1005: =IF(M1005="","",IFERROR(IF(INDEX(Parámetros!$B$14:$B$21,MATCH(I1005,Parámetros!$A$14:$A$21,0))="",Parámetros!$B$5,INDEX(Parámetros!$B$14:$B$21,MATCH(I1005,Parámetros!$A$14:$A$21,0))),Parámetros!$B$5)) | Q1005: =IF(O1005="","",(O1005-P1005)*100) | R1005: =IF(O1005="","",MAX(0,M1005*(P1005-O1005))) | S1005: =IF(OR(L1005="",L1005=0,N1005=""),"",N1005/1000/L1005) | AC1005: =IF(M1005="","",IF(AB1005="",M1005*Parámetros!$B$6,AB1005)) | AD1005: =IF(M1005="","",SUM(T1005:Z1005)+AC1005) | AE1005: =IF(OR(M1005="",N1005=""),"",M1005-N1005) | AF1005: =IF(AE1005="","",AE1005-AD1005) | AG1005: =IF(OR(AF1005="",M1005=0),"",AF1005/M1005) | AH1005: =IF(OR(AE1005="",N1005=0),"",AE1005/(N1005/1000)) | AI1005: =IF(O1005="","",M1005*P1005) | AJ1005: =IF(O1005="","",IF(O1005>1,"Error: rend > 100 %",IF(SUM(T1005:Z1005)=0,"Falta registrar pérdidas",IF(ABS(AG1005)>Parámetros!$B$7,"Revisar balance",IF(O1005<P1005,"Bajo meta","OK")))))

Sheet Resumen mensual
A1: Resumen mensual
A2: Rendimiento ponderado = Σ producción / Σ consumo. Año en Parámetros!B4.
A3: Año | B3: =Parámetros!B4 -> 2026
A5: Mes | B5: N° órdenes | C5: Consumo (kg) | D5: Producción (kg) | E5: Rend. metálico | F5: Meta ponderada | G5: Brecha | H5: Kg faltantes vs meta | I5: Órdenes bajo meta | J5: T1 (kg) | K5: T2 (kg) | L5: T3 (kg) | M5: T4 (kg) | N5: Fuera de medida (kg) | O5: Corto T4 (kg) | P5: Cobles / barras perdidas (kg) | Q5: Oxidación (kg) | R5: Pérdidas medidas (kg) | S5: Pérdidas SAP (kg) | T5: Delta no explicado (kg) | U5: Delta / consumo | V5: Pérdidas (kg/t) | W5: Productividad (t/h)
A6: =DATE($B$3,1,1) -> 46023 | B6: =COUNTIFS(Registro!$D$6:$D$1005,$A6,Registro!$M$6:$M$1005,">0") -> 0 | C6: =SUMIFS(Registro!$M$6:$M$1005,Registro!$D$6:$D$1005,$A6) -> 0 | D6: =SUMIFS(Registro!$N$6:$N$1005,Registro!$D$6:$D$1005,$A6) -> 0 | E6: =IF(C6=0,"",D6/C6) | F6: =IF(C6=0,"",SUMIFS(Registro!$AI$6:$AI$1005,Registro!$D$6:$D$1005,$A6)/C6) | G6: =IF(E6="","",(E6-F6)*100) | H6: =SUMIFS(Registro!$R$6:$R$1005,Registro!$D$6:$D$1005,$A6) -> 0 | I6: =COUNTIFS(Registro!$D$6:$D$1005,$A6,Registro!$AJ$6:$AJ$1005,"Bajo meta") -> 0 | J6: =SUMIFS(Registro!$T$6:$T$1005,Registro!$D$6:$D$1005,$A6) -> 0 | K6: =SUMIFS(Registro!$U$6:$U$1005,Registro!$D$6:$D$1005,$A6) -> 0 | L6: =SUMIFS(Registro!$V$6:$V$1005,Registro!$D$6:$D$1005,$A6) -> 0 | M6: =SUMIFS(Registro!$W$6:$W$1005,Registro!$D$6:$D$1005,$A6) -> 0 | N6: =SUMIFS(Registro!$X$6:$X$1005,Registro!$D$6:$D$1005,$A6) -> 0 | O6: =SUMIFS(Registro!$Y$6:$Y$1005,Registro!$D$6:$D$1005,$A6) -> 0 | P6: =SUMIFS(Registro!$Z$6:$Z$1005,Registro!$D$6:$D$1005,$A6) -> 0 | Q6: =SUMIFS(Registro!$AC$6:$AC$1005,Registro!$D$6:$D$1005,$A6) -> 0 | R6: =SUM(J6:Q6) -> 0 | S6: =SUMIFS(Registro!$AE$6:$AE$1005,Registro!$D$6:$D$1005,$A6) -> 0 | T6: =S6-R6 -> 0 | U6: =IF(C6=0,"",T6/C6) | V6: =IF(D6=0,"",S6/(D6/1000)) | W6: =IFERROR(D6/1000/SUMIFS(Registro!$L$6:$L$1005,Registro!$D$6:$D$1005,$A6),"")
A7: =DATE($B$3,2,1) -> 46054 | B7: =COUNTIFS(Registro!$D$6:$D$1005,$A7,Registro!$M$6:$M$1005,">0") -> 0 | C7: =SUMIFS(Registro!$M$6:$M$1005,Registro!$D$6:$D$1005,$A7) -> 0 | D7: =SUMIFS(Registro!$N$6:$N$1005,Registro!$D$6:$D$1005,$A7) -> 0 | E7: =IF(C7=0,"",D7/C7) | F7: =IF(C7=0,"",SUMIFS(Registro!$AI$6:$AI$1005,Registro!$D$6:$D$1005,$A7)/C7) | G7: =IF(E7="","",(E7-F7)*100) | H7: =SUMIFS(Registro!$R$6:$R$1005,Registro!$D$6:$D$1005,$A7) -> 0 | I7: =COUNTIFS(Registro!$D$6:$D$1005,$A7,Registro!$AJ$6:$AJ$1005,"Bajo meta") -> 0 | J7: =SUMIFS(Registro!$T$6:$T$1005,Registro!$D$6:$D$1005,$A7) -> 0 | K7: =SUMIFS(Registro!$U$6:$U$1005,Registro!$D$6:$D$1005,$A7) -> 0 | L7: =SUMIFS(Registro!$V$6:$V$1005,Registro!$D$6:$D$1005,$A7) -> 0 | M7: =SUMIFS(Registro!$W$6:$W$1005,Registro!$D$6:$D$1005,$A7) -> 0 | N7: =SUMIFS(Registro!$X$6:$X$1005,Registro!$D$6:$D$1005,$A7) -> 0 | O7: =SUMIFS(Registro!$Y$6:$Y$1005,Registro!$D$6:$D$1005,$A7) -> 0 | P7: =SUMIFS(Registro!$Z$6:$Z$1005,Registro!$D$6:$D$1005,$A7) -> 0 | Q7: =SUMIFS(Registro!$AC$6:$AC$1005,Registro!$D$6:$D$1005,$A7) -> 0 | R7: =SUM(J7:Q7) -> 0 | S7: =SUMIFS(Registro!$AE$6:$AE$1005,Registro!$D$6:$D$1005,$A7) -> 0 | T7: =S7-R7 -> 0 | U7: =IF(C7=0,"",T7/C7) | V7: =IF(D7=0,"",S7/(D7/1000)) | W7: =IFERROR(D7/1000/SUMIFS(Registro!$L$6:$L$1005,Registro!$D$6:$D$1005,$A7),"")
A8: =DATE($B$3,3,1) -> 46082 | B8: =COUNTIFS(Registro!$D$6:$D$1005,$A8,Registro!$M$6:$M$1005,">0") -> 0 | C8: =SUMIFS(Registro!$M$6:$M$1005,Registro!$D$6:$D$1005,$A8) -> 0 | D8: =SUMIFS(Registro!$N$6:$N$1005,Registro!$D$6:$D$1005,$A8) -> 0 | E8: =IF(C8=0,"",D8/C8) | F8: =IF(C8=0,"",SUMIFS(Registro!$AI$6:$AI$1005,Registro!$D$6:$D$1005,$A8)/C8) | G8: =IF(E8="","",(E8-F8)*100) | H8: =SUMIFS(Registro!$R$6:$R$1005,Registro!$D$6:$D$1005,$A8) -> 0 | I8: =COUNTIFS(Registro!$D$6:$D$1005,$A8,Registro!$AJ$6:$AJ$1005,"Bajo meta") -> 0 | J8: =SUMIFS(Registro!$T$6:$T$1005,Registro!$D$6:$D$1005,$A8) -> 0 | K8: =SUMIFS(Registro!$U$6:$U$1005,Registro!$D$6:$D$1005,$A8) -> 0 | L8: =SUMIFS(Registro!$V$6:$V$1005,Registro!$D$6:$D$1005,$A8) -> 0 | M8: =SUMIFS(Registro!$W$6:$W$1005,Registro!$D$6:$D$1005,$A8) -> 0 | N8: =SUMIFS(Registro!$X$6:$X$1005,Registro!$D$6:$D$1005,$A8) -> 0 | O8: =SUMIFS(Registro!$Y$6:$Y$1005,Registro!$D$6:$D$1005,$A8) -> 0 | P8: =SUMIFS(Registro!$Z$6:$Z$1005,Registro!$D$6:$D$1005,$A8) -> 0 | Q8: =SUMIFS(Registro!$AC$6:$AC$1005,Registro!$D$6:$D$1005,$A8) -> 0 | R8: =SUM(J8:Q8) -> 0 | S8: =SUMIFS(Registro!$AE$6:$AE$1005,Registro!$D$6:$D$1005,$A8) -> 0 | T8: =S8-R8 -> 0 | U8: =IF(C8=0,"",T8/C8) | V8: =IF(D8=0,"",S8/(D8/1000)) | W8: =IFERROR(D8/1000/SUMIFS(Registro!$L$6:$L$1005,Registro!$D$6:$D$1005,$A8),"")
A9: =DATE($B$3,4,1) -> 46113 | B9: =COUNTIFS(Registro!$D$6:$D$1005,$A9,Registro!$M$6:$M$1005,">0") -> 0 | C9: =SUMIFS(Registro!$M$6:$M$1005,Registro!$D$6:$D$1005,$A9) -> 0 | D9: =SUMIFS(Registro!$N$6:$N$1005,Registro!$D$6:$D$1005,$A9) -> 0 | E9: =IF(C9=0,"",D9/C9) | F9: =IF(C9=0,"",SUMIFS(Registro!$AI$6:$AI$1005,Registro!$D$6:$D$1005,$A9)/C9) | G9: =IF(E9="","",(E9-F9)*100) | H9: =SUMIFS(Registro!$R$6:$R$1005,Registro!$D$6:$D$1005,$A9) -> 0 | I9: =COUNTIFS(Registro!$D$6:$D$1005,$A9,Registro!$AJ$6:$AJ$1005,"Bajo meta") -> 0 | J9: =SUMIFS(Registro!$T$6:$T$1005,Registro!$D$6:$D$1005,$A9) -> 0 | K9: =SUMIFS(Registro!$U$6:$U$1005,Registro!$D$6:$D$1005,$A9) -> 0 | L9: =SUMIFS(Registro!$V$6:$V$1005,Registro!$D$6:$D$1005,$A9) -> 0 | M9: =SUMIFS(Registro!$W$6:$W$1005,Registro!$D$6:$D$1005,$A9) -> 0 | N9: =SUMIFS(Registro!$X$6:$X$1005,Registro!$D$6:$D$1005,$A9) -> 0 | O9: =SUMIFS(Registro!$Y$6:$Y$1005,Registro!$D$6:$D$1005,$A9) -> 0 | P9: =SUMIFS(Registro!$Z$6:$Z$1005,Registro!$D$6:$D$1005,$A9) -> 0 | Q9: =SUMIFS(Registro!$AC$6:$AC$1005,Registro!$D$6:$D$1005,$A9) -> 0 | R9: =SUM(J9:Q9) -> 0 | S9: =SUMIFS(Registro!$AE$6:$AE$1005,Registro!$D$6:$D$1005,$A9) -> 0 | T9: =S9-R9 -> 0 | U9: =IF(C9=0,"",T9/C9) | V9: =IF(D9=0,"",S9/(D9/1000)) | W9: =IFERROR(D9/1000/SUMIFS(Registro!$L$6:$L$1005,Registro!$D$6:$D$1005,$A9),"")
A10: =DATE($B$3,5,1) -> 46143 | B10: =COUNTIFS(Registro!$D$6:$D$1005,$A10,Registro!$M$6:$M$1005,">0") -> 0 | C10: =SUMIFS(Registro!$M$6:$M$1005,Registro!$D$6:$D$1005,$A10) -> 0 | D10: =SUMIFS(Registro!$N$6:$N$1005,Registro!$D$6:$D$1005,$A10) -> 0 | E10: =IF(C10=0,"",D10/C10) | F10: =IF(C10=0,"",SUMIFS(Registro!$AI$6:$AI$1005,Registro!$D$6:$D$1005,$A10)/C10) | G10: =IF(E10="","",(E10-F10)*100) | H10: =SUMIFS(Registro!$R$6:$R$1005,Registro!$D$6:$D$1005,$A10) -> 0 | I10: =COUNTIFS(Registro!$D$6:$D$1005,$A10,Registro!$AJ$6:$AJ$1005,"Bajo meta") -> 0 | J10: =SUMIFS(Registro!$T$6:$T$1005,Registro!$D$6:$D$1005,$A10) -> 0 | K10: =SUMIFS(Registro!$U$6:$U$1005,Registro!$D$6:$D$1005,$A10) -> 0 | L10: =SUMIFS(Registro!$V$6:$V$1005,Registro!$D$6:$D$1005,$A10) -> 0 | M10: =SUMIFS(Registro!$W$6:$W$1005,Registro!$D$6:$D$1005,$A10) -> 0 | N10: =SUMIFS(Registro!$X$6:$X$1005,Registro!$D$6:$D$1005,$A10) -> 0 | O10: =SUMIFS(Registro!$Y$6:$Y$1005,Registro!$D$6:$D$1005,$A10) -> 0 | P10: =SUMIFS(Registro!$Z$6:$Z$1005,Registro!$D$6:$D$1005,$A10) -> 0 | Q10: =SUMIFS(Registro!$AC$6:$AC$1005,Registro!$D$6:$D$1005,$A10) -> 0 | R10: =SUM(J10:Q10) -> 0 | S10: =SUMIFS(Registro!$AE$6:$AE$1005,Registro!$D$6:$D$1005,$A10) -> 0 | T10: =S10-R10 -> 0 | U10: =IF(C10=0,"",T10/C10) | V10: =IF(D10=0,"",S10/(D10/1000)) | W10: =IFERROR(D10/1000/SUMIFS(Registro!$L$6:$L$1005,Registro!$D$6:$D$1005,$A10),"")
A11: =DATE($B$3,6,1) -> 46174 | B11: =COUNTIFS(Registro!$D$6:$D$1005,$A11,Registro!$M$6:$M$1005,">0") -> 0 | C11: =SUMIFS(Registro!$M$6:$M$1005,Registro!$D$6:$D$1005,$A11) -> 0 | D11: =SUMIFS(Registro!$N$6:$N$1005,Registro!$D$6:$D$1005,$A11) -> 0 | E11: =IF(C11=0,"",D11/C11) | F11: =IF(C11=0,"",SUMIFS(Registro!$AI$6:$AI$1005,Registro!$D$6:$D$1005,$A11)/C11) | G11: =IF(E11="","",(E11-F11)*100) | H11: =SUMIFS(Registro!$R$6:$R$1005,Registro!$D$6:$D$1005,$A11) -> 0 | I11: =COUNTIFS(Registro!$D$6:$D$1005,$A11,Registro!$AJ$6:$AJ$1005,"Bajo meta") -> 0 | J11: =SUMIFS(Registro!$T$6:$T$1005,Registro!$D$6:$D$1005,$A11) -> 0 | K11: =SUMIFS(Registro!$U$6:$U$1005,Registro!$D$6:$D$1005,$A11) -> 0 | L11: =SUMIFS(Registro!$V$6:$V$1005,Registro!$D$6:$D$1005,$A11) -> 0 | M11: =SUMIFS(Registro!$W$6:$W$1005,Registro!$D$6:$D$1005,$A11) -> 0 | N11: =SUMIFS(Registro!$X$6:$X$1005,Registro!$D$6:$D$1005,$A11) -> 0 | O11: =SUMIFS(Registro!$Y$6:$Y$1005,Registro!$D$6:$D$1005,$A11) -> 0 | P11: =SUMIFS(Registro!$Z$6:$Z$1005,Registro!$D$6:$D$1005,$A11) -> 0 | Q11: =SUMIFS(Registro!$AC$6:$AC$1005,Registro!$D$6:$D$1005,$A11) -> 0 | R11: =SUM(J11:Q11) -> 0 | S11: =SUMIFS(Registro!$AE$6:$AE$1005,Registro!$D$6:$D$1005,$A11) -> 0 | T11: =S11-R11 -> 0 | U11: =IF(C11=0,"",T11/C11) | V11: =IF(D11=0,"",S11/(D11/1000)) | W11: =IFERROR(D11/1000/SUMIFS(Registro!$L$6:$L$1005,Registro!$D$6:$D$1005,$A11),"")
A12: =DATE($B$3,7,1) -> 46204 | B12: =COUNTIFS(Registro!$D$6:$D$1005,$A12,Registro!$M$6:$M$1005,">0") -> 0 | C12: =SUMIFS(Registro!$M$6:$M$1005,Registro!$D$6:$D$1005,$A12) -> 0 | D12: =SUMIFS(Registro!$N$6:$N$1005,Registro!$D$6:$D$1005,$A12) -> 0 | E12: =IF(C12=0,"",D12/C12) | F12: =IF(C12=0,"",SUMIFS(Registro!$AI$6:$AI$1005,Registro!$D$6:$D$1005,$A12)/C12) | G12: =IF(E12="","",(E12-F12)*100) | H12: =SUMIFS(Registro!$R$6:$R$1005,Registro!$D$6:$D$1005,$A12) -> 0 | I12: =COUNTIFS(Registro!$D$6:$D$1005,$A12,Registro!$AJ$6:$AJ$1005,"Bajo meta") -> 0 | J12: =SUMIFS(Registro!$T$6:$T$1005,Registro!$D$6:$D$1005,$A12) -> 0 | K12: =SUMIFS(Registro!$U$6:$U$1005,Registro!$D$6:$D$1005,$A12) -> 0 | L12: =SUMIFS(Registro!$V$6:$V$1005,Registro!$D$6:$D$1005,$A12) -> 0 | M12: =SUMIFS(Registro!$W$6:$W$1005,Registro!$D$6:$D$1005,$A12) -> 0 | N12: =SUMIFS(Registro!$X$6:$X$1005,Registro!$D$6:$D$1005,$A12) -> 0 | O12: =SUMIFS(Registro!$Y$6:$Y$1005,Registro!$D$6:$D$1005,$A12) -> 0 | P12: =SUMIFS(Registro!$Z$6:$Z$1005,Registro!$D$6:$D$1005,$A12) -> 0 | Q12: =SUMIFS(Registro!$AC$6:$AC$1005,Registro!$D$6:$D$1005,$A12) -> 0 | R12: =SUM(J12:Q12) -> 0 | S12: =SUMIFS(Registro!$AE$6:$AE$1005,Registro!$D$6:$D$1005,$A12) -> 0 | T12: =S12-R12 -> 0 | U12: =IF(C12=0,"",T12/C12) | V12: =IF(D12=0,"",S12/(D12/1000)) | W12: =IFERROR(D12/1000/SUMIFS(Registro!$L$6:$L$1005,Registro!$D$6:$D$1005,$A12),"")
A13: =DATE($B$3,8,1) -> 46235 | B13: =COUNTIFS(Registro!$D$6:$D$1005,$A13,Registro!$M$6:$M$1005,">0") -> 0 | C13: =SUMIFS(Registro!$M$6:$M$1005,Registro!$D$6:$D$1005,$A13) -> 0 | D13: =SUMIFS(Registro!$N$6:$N$1005,Registro!$D$6:$D$1005,$A13) -> 0 | E13: =IF(C13=0,"",D13/C13) | F13: =IF(C13=0,"",SUMIFS(Registro!$AI$6:$AI$1005,Registro!$D$6:$D$1005,$A13)/C13) | G13: =IF(E13="","",(E13-F13)*100) | H13: =SUMIFS(Registro!$R$6:$R$1005,Registro!$D$6:$D$1005,$A13) -> 0 | I13: =COUNTIFS(Registro!$D$6:$D$1005,$A13,Registro!$AJ$6:$AJ$1005,"Bajo meta") -> 0 | J13: =SUMIFS(Registro!$T$6:$T$1005,Registro!$D$6:$D$1005,$A13) -> 0 | K13: =SUMIFS(Registro!$U$6:$U$1005,Registro!$D$6:$D$1005,$A13) -> 0 | L13: =SUMIFS(Registro!$V$6:$V$1005,Registro!$D$6:$D$1005,$A13) -> 0 | M13: =SUMIFS(Registro!$W$6:$W$1005,Registro!$D$6:$D$1005,$A13) -> 0 | N13: =SUMIFS(Registro!$X$6:$X$1005,Registro!$D$6:$D$1005,$A13) -> 0 | O13: =SUMIFS(Registro!$Y$6:$Y$1005,Registro!$D$6:$D$1005,$A13) -> 0 | P13: =SUMIFS(Registro!$Z$6:$Z$1005,Registro!$D$6:$D$1005,$A13) -> 0 | Q13: =SUMIFS(Registro!$AC$6:$AC$1005,Registro!$D$6:$D$1005,$A13) -> 0 | R13: =SUM(J13:Q13) -> 0 | S13: =SUMIFS(Registro!$AE$6:$AE$1005,Registro!$D$6:$D$1005,$A13) -> 0 | T13: =S13-R13 -> 0 | U13: =IF(C13=0,"",T13/C13) | V13: =IF(D13=0,"",S13/(D13/1000)) | W13: =IFERROR(D13/1000/SUMIFS(Registro!$L$6:$L$1005,Registro!$D$6:$D$1005,$A13),"")
A14: =DATE($B$3,9,1) -> 46266 | B14: =COUNTIFS(Registro!$D$6:$D$1005,$A14,Registro!$M$6:$M$1005,">0") -> 0 | C14: =SUMIFS(Registro!$M$6:$M$1005,Registro!$D$6:$D$1005,$A14) -> 0 | D14: =SUMIFS(Registro!$N$6:$N$1005,Registro!$D$6:$D$1005,$A14) -> 0 | E14: =IF(C14=0,"",D14/C14) | F14: =IF(C14=0,"",SUMIFS(Registro!$AI$6:$AI$1005,Registro!$D$6:$D$1005,$A14)/C14) | G14: =IF(E14="","",(E14-F14)*100) | H14: =SUMIFS(Registro!$R$6:$R$1005,Registro!$D$6:$D$1005,$A14) -> 0 | I14: =COUNTIFS(Registro!$D$6:$D$1005,$A14,Registro!$AJ$6:$AJ$1005,"Bajo meta") -> 0 | J14: =SUMIFS(Registro!$T$6:$T$1005,Registro!$D$6:$D$1005,$A14) -> 0 | K14: =SUMIFS(Registro!$U$6:$U$1005,Registro!$D$6:$D$1005,$A14) -> 0 | L14: =SUMIFS(Registro!$V$6:$V$1005,Registro!$D$6:$D$1005,$A14) -> 0 | M14: =SUMIFS(Registro!$W$6:$W$1005,Registro!$D$6:$D$1005,$A14) -> 0 | N14: =SUMIFS(Registro!$X$6:$X$1005,Registro!$D$6:$D$1005,$A14) -> 0 | O14: =SUMIFS(Registro!$Y$6:$Y$1005,Registro!$D$6:$D$1005,$A14) -> 0 | P14: =SUMIFS(Registro!$Z$6:$Z$1005,Registro!$D$6:$D$1005,$A14) -> 0 | Q14: =SUMIFS(Registro!$AC$6:$AC$1005,Registro!$D$6:$D$1005,$A14) -> 0 | R14: =SUM(J14:Q14) -> 0 | S14: =SUMIFS(Registro!$AE$6:$AE$1005,Registro!$D$6:$D$1005,$A14) -> 0 | T14: =S14-R14 -> 0 | U14: =IF(C14=0,"",T14/C14) | V14: =IF(D14=0,"",S14/(D14/1000)) | W14: =IFERROR(D14/1000/SUMIFS(Registro!$L$6:$L$1005,Registro!$D$6:$D$1005,$A14),"")
A15: =DATE($B$3,10,1) -> 46296 | B15: =COUNTIFS(Registro!$D$6:$D$1005,$A15,Registro!$M$6:$M$1005,">0") -> 0 | C15: =SUMIFS(Registro!$M$6:$M$1005,Registro!$D$6:$D$1005,$A15) -> 0 | D15: =SUMIFS(Registro!$N$6:$N$1005,Registro!$D$6:$D$1005,$A15) -> 0 | E15: =IF(C15=0,"",D15/C15) | F15: =IF(C15=0,"",SUMIFS(Registro!$AI$6:$AI$1005,Registro!$D$6:$D$1005,$A15)/C15) | G15: =IF(E15="","",(E15-F15)*100) | H15: =SUMIFS(Registro!$R$6:$R$1005,Registro!$D$6:$D$1005,$A15) -> 0 | I15: =COUNTIFS(Registro!$D$6:$D$1005,$A15,Registro!$AJ$6:$AJ$1005,"Bajo meta") -> 0 | J15: =SUMIFS(Registro!$T$6:$T$1005,Registro!$D$6:$D$1005,$A15) -> 0 | K15: =SUMIFS(Registro!$U$6:$U$1005,Registro!$D$6:$D$1005,$A15) -> 0 | L15: =SUMIFS(Registro!$V$6:$V$1005,Registro!$D$6:$D$1005,$A15) -> 0 | M15: =SUMIFS(Registro!$W$6:$W$1005,Registro!$D$6:$D$1005,$A15) -> 0 | N15: =SUMIFS(Registro!$X$6:$X$1005,Registro!$D$6:$D$1005,$A15) -> 0 | O15: =SUMIFS(Registro!$Y$6:$Y$1005,Registro!$D$6:$D$1005,$A15) -> 0 | P15: =SUMIFS(Registro!$Z$6:$Z$1005,Registro!$D$6:$D$1005,$A15) -> 0 | Q15: =SUMIFS(Registro!$AC$6:$AC$1005,Registro!$D$6:$D$1005,$A15) -> 0 | R15: =SUM(J15:Q15) -> 0 | S15: =SUMIFS(Registro!$AE$6:$AE$1005,Registro!$D$6:$D$1005,$A15) -> 0 | T15: =S15-R15 -> 0 | U15: =IF(C15=0,"",T15/C15) | V15: =IF(D15=0,"",S15/(D15/1000)) | W15: =IFERROR(D15/1000/SUMIFS(Registro!$L$6:$L$1005,Registro!$D$6:$D$1005,$A15),"")
A16: =DATE($B$3,11,1) -> 46327 | B16: =COUNTIFS(Registro!$D$6:$D$1005,$A16,Registro!$M$6:$M$1005,">0") -> 0 | C16: =SUMIFS(Registro!$M$6:$M$1005,Registro!$D$6:$D$1005,$A16) -> 0 | D16: =SUMIFS(Registro!$N$6:$N$1005,Registro!$D$6:$D$1005,$A16) -> 0 | E16: =IF(C16=0,"",D16/C16) | F16: =IF(C16=0,"",SUMIFS(Registro!$AI$6:$AI$1005,Registro!$D$6:$D$1005,$A16)/C16) | G16: =IF(E16="","",(E16-F16)*100) | H16: =SUMIFS(Registro!$R$6:$R$1005,Registro!$D$6:$D$1005,$A16) -> 0 | I16: =COUNTIFS(Registro!$D$6:$D$1005,$A16,Registro!$AJ$6:$AJ$1005,"Bajo meta") -> 0 | J16: =SUMIFS(Registro!$T$6:$T$1005,Registro!$D$6:$D$1005,$A16) -> 0 | K16: =SUMIFS(Registro!$U$6:$U$1005,Registro!$D$6:$D$1005,$A16) -> 0 | L16: =SUMIFS(Registro!$V$6:$V$1005,Registro!$D$6:$D$1005,$A16) -> 0 | M16: =SUMIFS(Registro!$W$6:$W$1005,Registro!$D$6:$D$1005,$A16) -> 0 | N16: =SUMIFS(Registro!$X$6:$X$1005,Registro!$D$6:$D$1005,$A16) -> 0 | O16: =SUMIFS(Registro!$Y$6:$Y$1005,Registro!$D$6:$D$1005,$A16) -> 0 | P16: =SUMIFS(Registro!$Z$6:$Z$1005,Registro!$D$6:$D$1005,$A16) -> 0 | Q16: =SUMIFS(Registro!$AC$6:$AC$1005,Registro!$D$6:$D$1005,$A16) -> 0 | R16: =SUM(J16:Q16) -> 0 | S16: =SUMIFS(Registro!$AE$6:$AE$1005,Registro!$D$6:$D$1005,$A16) -> 0 | T16: =S16-R16 -> 0 | U16: =IF(C16=0,"",T16/C16) | V16: =IF(D16=0,"",S16/(D16/1000)) | W16: =IFERROR(D16/1000/SUMIFS(Registro!$L$6:$L$1005,Registro!$D$6:$D$1005,$A16),"")
A17: =DATE($B$3,12,1) -> 46357 | B17: =COUNTIFS(Registro!$D$6:$D$1005,$A17,Registro!$M$6:$M$1005,">0") -> 0 | C17: =SUMIFS(Registro!$M$6:$M$1005,Registro!$D$6:$D$1005,$A17) -> 0 | D17: =SUMIFS(Registro!$N$6:$N$1005,Registro!$D$6:$D$1005,$A17) -> 0 | E17: =IF(C17=0,"",D17/C17) | F17: =IF(C17=0,"",SUMIFS(Registro!$AI$6:$AI$1005,Registro!$D$6:$D$1005,$A17)/C17) | G17: =IF(E17="","",(E17-F17)*100) | H17: =SUMIFS(Registro!$R$6:$R$1005,Registro!$D$6:$D$1005,$A17) -> 0 | I17: =COUNTIFS(Registro!$D$6:$D$1005,$A17,Registro!$AJ$6:$AJ$1005,"Bajo meta") -> 0 | J17: =SUMIFS(Registro!$T$6:$T$1005,Registro!$D$6:$D$1005,$A17) -> 0 | K17: =SUMIFS(Registro!$U$6:$U$1005,Registro!$D$6:$D$1005,$A17) -> 0 | L17: =SUMIFS(Registro!$V$6:$V$1005,Registro!$D$6:$D$1005,$A17) -> 0 | M17: =SUMIFS(Registro!$W$6:$W$1005,Registro!$D$6:$D$1005,$A17) -> 0 | N17: =SUMIFS(Registro!$X$6:$X$1005,Registro!$D$6:$D$1005,$A17) -> 0 | O17: =SUMIFS(Registro!$Y$6:$Y$1005,Registro!$D$6:$D$1005,$A17) -> 0 | P17: =SUMIFS(Registro!$Z$6:$Z$1005,Registro!$D$6:$D$1005,$A17) -> 0 | Q17: =SUMIFS(Registro!$AC$6:$AC$1005,Registro!$D$6:$D$1005,$A17) -> 0 | R17: =SUM(J17:Q17) -> 0 | S17: =SUMIFS(Registro!$AE$6:$AE$1005,Registro!$D$6:$D$1005,$A17) -> 0 | T17: =S17-R17 -> 0 | U17: =IF(C17=0,"",T17/C17) | V17: =IF(D17=0,"",S17/(D17/1000)) | W17: =IFERROR(D17/1000/SUMIFS(Registro!$L$6:$L$1005,Registro!$D$6:$D$1005,$A17),"")
A18: Año | B18: =SUM(B6:B17) -> 0 | C18: =SUM(C6:C17) -> 0 | D18: =SUM(D6:D17) -> 0 | E18: =IF(C18=0,"",D18/C18) | F18: =IF(C18=0,"",SUMIFS(Registro!$AI$6:$AI$1005,Registro!$D$6:$D$1005,">="&A6,Registro!$D$6:$D$1005,"<="&A17)/C18) | G18: =IF(E18="","",(E18-F18)*100) | H18: =SUM(H6:H17) -> 0 | I18: =SUM(I6:I17) -> 0 | J18: =SUM(J6:J17) -> 0 | K18: =SUM(K6:K17) -> 0 | L18: =SUM(L6:L17) -> 0 | M18: =SUM(M6:M17) -> 0 | N18: =SUM(N6:N17) -> 0 | O18: =SUM(O6:O17) -> 0 | ... T18: =SUM(T6:T17) -> 0 | U18: =IF(C18=0,"",T18/C18) | V18: =IF(D18=0,"",S18/(D18/1000)) | W18: =IFERROR(D18/1000/SUMIFS(Registro!$L$6:$L$1005,Registro!$D$6:$D$1005,">="&A6,Registro!$D$6:$D$1005,"<="&A17),"")
A21: Rendimiento por grupo y mes
A22: Grupo | B22: =A6 -> 46023 | C22: =A7 -> 46054 | D22: =A8 -> 46082 | E22: =A9 -> 46113 | F22: =A10 -> 46143 | G22: =A11 -> 46174 | H22: =A12 -> 46204 | I22: =A13 -> 46235 | J22: =A14 -> 46266 | K22: =A15 -> 46296 | L22: =A16 -> 46327 | M22: =A17 -> 46357 | N22: Año | O22: Meta
A23: =Parámetros!A14 -> B Hormigón | B23: =IFERROR(SUMIFS(Registro!$N$6:$N$1005,Registro!$I$6:$I$1005,$A23,Registro!$D$6:$D$1005,B$22)/SUMIFS(Registro!$M$6:$M$1005,Registro!$I$6:$I$1005,$A23,Registro!$D$6:$D$1005,B$22),"") | C23: =IFERROR(SUMIFS(Registro!$N$6:$N$1005,Registro!$I$6:$I$1005,$A23,Registro!$D$6:$D$1005,C$22)/SUMIFS(Registro!$M$6:$M$1005,Registro!$I$6:$I$1005,$A23,Registro!$D$6:$D$1005,C$22),"") | D23: =IFERROR(SUMIFS(Registro!$N$6:$N$1005,Registro!$I$6:$I$1005,$A23,Registro!$D$6:$D$1005,D$22)/SUMIFS(Registro!$M$6:$M$1005,Registro!$I$6:$I$1005,$A23,Registro!$D$6:$D$1005,D$22),"") | E23: =IFERROR(SUMIFS(Registro!$N$6:$N$1005,Registro!$I$6:$I$1005,$A23,Registro!$D$6:$D$1005,E$22)/SUMIFS(Registro!$M$6:$M$1005,Registro!$I$6:$I$1005,$A23,Registro!$D$6:$D$1005,E$22),"") | F23: =IFERROR(SUMIFS(Registro!$N$6:$N$1005,Registro!$I$6:$I$1005,$A23,Registro!$D$6:$D$1005,F$22)/SUMIFS(Registro!$M$6:$M$1005,Registro!$I$6:$I$1005,$A23,Registro!$D$6:$D$1005,F$22),"") | G23: =IFERROR(SUMIFS(Registro!$N$6:$N$1005,Registro!$I$6:$I$1005,$A23,Registro!$D$6:$D$1005,G$22)/SUMIFS(Registro!$M$6:$M$1005,Registro!$I$6:$I$1005,$A23,Registro!$D$6:$D$1005,G$22),"") | H23: =IFERROR(SUMIFS(Registro!$N$6:$N$1005,Registro!$I$6:$I$1005,$A23,Registro!$D$6:$D$1005,H$22)/SUMIFS(Registro!$M$6:$M$1005,Registro!$I$6:$I$1005,$A23,Registro!$D$6:$D$1005,H$22),"") | I23: =IFERROR(SUMIFS(Registro!$N$6:$N$1005,Registro!$I$6:$I$1005,$A23,Registro!$D$6:$D$1005,I$22)/SUMIFS(Registro!$M$6:$M$1005,Registro!$I$6:$I$1005,$A23,Registro!$D$6:$D$1005,I$22),"") | ... M23: =IFERROR(SUMIFS(Registro!$N$6:$N$1005,Registro!$I$6:$I$1005,$A23,Registro!$D$6:$D$1005,M$22)/SUMIFS(Registro!$M$6:$M$1005,Registro!$I$6:$I$1005,$A23,Registro!$D$6:$D$1005,M$22),"") | N23: =IFERROR(SUMIFS(Registro!$N$6:$N$1005,Registro!$I$6:$I$1005,$A23,Registro!$D$6:$D$1005,">="&$A$6,Registro!$D$6:$D$1005,"<="&$A$17)/SUMIFS(Registro!$M$6:$M$1005,Registro!$I$6:$I$1005,$A23,Registro!$D$6:$D$1005,">="&$A$6,Registro!$D$6:$D$1005,"<="&$A$17),"") | O23: =IF(Parámetros!B14="",Parámetros!$B$5,Parámetros!B14) -> 0.9576
A24: =Parámetros!A15 -> Redondo liso | B24: =IFERROR(SUMIFS(Registro!$N$6:$N$1005,Registro!$I$6:$I$1005,$A24,Registro!$D$6:$D$1005,B$22)/SUMIFS(Registro!$M$6:$M$1005,Registro!$I$6:$I$1005,$A24,Registro!$D$6:$D$1005,B$22),"") | C24: =IFERROR(SUMIFS(Registro!$N$6:$N$1005,Registro!$I$6:$I$1005,$A24,Registro!$D$6:$D$1005,C$22)/SUMIFS(Registro!$M$6:$M$1005,Registro!$I$6:$I$1005,$A24,Registro!$D$6:$D$1005,C$22),"") | D24: =IFERROR(SUMIFS(Registro!$N$6:$N$1005,Registro!$I$6:$I$1005,$A24,Registro!$D$6:$D$1005,D$22)/SUMIFS(Registro!$M$6:$M$1005,Registro!$I$6:$I$1005,$A24,Registro!$D$6:$D$1005,D$22),"") | E24: =IFERROR(SUMIFS(Registro!$N$6:$N$1005,Registro!$I$6:$I$1005,$A24,Registro!$D$6:$D$1005,E$22)/SUMIFS(Registro!$M$6:$M$1005,Registro!$I$6:$I$1005,$A24,Registro!$D$6:$D$1005,E$22),"") | F24: =IFERROR(SUMIFS(Registro!$N$6:$N$1005,Registro!$I$6:$I$1005,$A24,Registro!$D$6:$D$1005,F$22)/SUMIFS(Registro!$M$6:$M$1005,Registro!$I$6:$I$1005,$A24,Registro!$D$6:$D$1005,F$22),"") | G24: =IFERROR(SUMIFS(Registro!$N$6:$N$1005,Registro!$I$6:$I$1005,$A24,Registro!$D$6:$D$1005,G$22)/SUMIFS(Registro!$M$6:$M$1005,Registro!$I$6:$I$1005,$A24,Registro!$D$6:$D$1005,G$22),"") | H24: =IFERROR(SUMIFS(Registro!$N$6:$N$1005,Registro!$I$6:$I$1005,$A24,Registro!$D$6:$D$1005,H$22)/SUMIFS(Registro!$M$6:$M$1005,Registro!$I$6:$I$1005,$A24,Registro!$D$6:$D$1005,H$22),"") | I24: =IFERROR(SUMIFS(Registro!$N$6:$N$1005,Registro!$I$6:$I$1005,$A24,Registro!$D$6:$D$1005,I$22)/SUMIFS(Registro!$M$6:$M$1005,Registro!$I$6:$I$1005,$A24,Registro!$D$6:$D$1005,I$22),"") | ... M24: =IFERROR(SUMIFS(Registro!$N$6:$N$1005,Registro!$I$6:$I$1005,$A24,Registro!$D$6:$D$1005,M$22)/SUMIFS(Registro!$M$6:$M$1005,Registro!$I$6:$I$1005,$A24,Registro!$D$6:$D$1005,M$22),"") | N24: =IFERROR(SUMIFS(Registro!$N$6:$N$1005,Registro!$I$6:$I$1005,$A24,Registro!$D$6:$D$1005,">="&$A$6,Registro!$D$6:$D$1005,"<="&$A$17)/SUMIFS(Registro!$M$6:$M$1005,Registro!$I$6:$I$1005,$A24,Registro!$D$6:$D$1005,">="&$A$6,Registro!$D$6:$D$1005,"<="&$A$17),"") | O24: =IF(Parámetros!B15="",Parámetros!$B$5,Parámetros!B15) -> 0.9538
A25: =Parámetros!A16 -> Plana | B25: =IFERROR(SUMIFS(Registro!$N$6:$N$1005,Registro!$I$6:$I$1005,$A25,Registro!$D$6:$D$1005,B$22)/SUMIFS(Registro!$M$6:$M$1005,Registro!$I$6:$I$1005,$A25,Registro!$D$6:$D$1005,B$22),"") | C25: =IFERROR(SUMIFS(Registro!$N$6:$N$1005,Registro!$I$6:$I$1005,$A25,Registro!$D$6:$D$1005,C$22)/SUMIFS(Registro!$M$6:$M$1005,Registro!$I$6:$I$1005,$A25,Registro!$D$6:$D$1005,C$22),"") | D25: =IFERROR(SUMIFS(Registro!$N$6:$N$1005,Registro!$I$6:$I$1005,$A25,Registro!$D$6:$D$1005,D$22)/SUMIFS(Registro!$M$6:$M$1005,Registro!$I$6:$I$1005,$A25,Registro!$D$6:$D$1005,D$22),"") | E25: =IFERROR(SUMIFS(Registro!$N$6:$N$1005,Registro!$I$6:$I$1005,$A25,Registro!$D$6:$D$1005,E$22)/SUMIFS(Registro!$M$6:$M$1005,Registro!$I$6:$I$1005,$A25,Registro!$D$6:$D$1005,E$22),"") | F25: =IFERROR(SUMIFS(Registro!$N$6:$N$1005,Registro!$I$6:$I$1005,$A25,Registro!$D$6:$D$1005,F$22)/SUMIFS(Registro!$M$6:$M$1005,Registro!$I$6:$I$1005,$A25,Registro!$D$6:$D$1005,F$22),"") | G25: =IFERROR(SUMIFS(Registro!$N$6:$N$1005,Registro!$I$6:$I$1005,$A25,Registro!$D$6:$D$1005,G$22)/SUMIFS(Registro!$M$6:$M$1005,Registro!$I$6:$I$1005,$A25,Registro!$D$6:$D$1005,G$22),"") | H25: =IFERROR(SUMIFS(Registro!$N$6:$N$1005,Registro!$I$6:$I$1005,$A25,Registro!$D$6:$D$1005,H$22)/SUMIFS(Registro!$M$6:$M$1005,Registro!$I$6:$I$1005,$A25,Registro!$D$6:$D$1005,H$22),"") | I25: =IFERROR(SUMIFS(Registro!$N$6:$N$1005,Registro!$I$6:$I$1005,$A25,Registro!$D$6:$D$1005,I$22)/SUMIFS(Registro!$M$6:$M$1005,Registro!$I$6:$I$1005,$A25,Registro!$D$6:$D$1005,I$22),"") | ... M25: =IFERROR(SUMIFS(Registro!$N$6:$N$1005,Registro!$I$6:$I$1005,$A25,Registro!$D$6:$D$1005,M$22)/SUMIFS(Registro!$M$6:$M$1005,Registro!$I$6:$I$1005,$A25,Registro!$D$6:$D$1005,M$22),"") | N25: =IFERROR(SUMIFS(Registro!$N$6:$N$1005,Registro!$I$6:$I$1005,$A25,Registro!$D$6:$D$1005,">="&$A$6,Registro!$D$6:$D$1005,"<="&$A$17)/SUMIFS(Registro!$M$6:$M$1005,Registro!$I$6:$I$1005,$A25,Registro!$D$6:$D$1005,">="&$A$6,Registro!$D$6:$D$1005,"<="&$A$17),"") | O25: =IF(Parámetros!B16="",Parámetros!$B$5,Parámetros!B16) -> 0.9609
A26: =Parámetros!A17 -> Ángulo | B26: =IFERROR(SUMIFS(Registro!$N$6:$N$1005,Registro!$I$6:$I$1005,$A26,Registro!$D$6:$D$1005,B$22)/SUMIFS(Registro!$M$6:$M$1005,Registro!$I$6:$I$1005,$A26,Registro!$D$6:$D$1005,B$22),"") | C26: =IFERROR(SUMIFS(Registro!$N$6:$N$1005,Registro!$I$6:$I$1005,$A26,Registro!$D$6:$D$1005,C$22)/SUMIFS(Registro!$M$6:$M$1005,Registro!$I$6:$I$1005,$A26,Registro!$D$6:$D$1005,C$22),"") | D26: =IFERROR(SUMIFS(Registro!$N$6:$N$1005,Registro!$I$6:$I$1005,$A26,Registro!$D$6:$D$1005,D$22)/SUMIFS(Registro!$M$6:$M$1005,Registro!$I$6:$I$1005,$A26,Registro!$D$6:$D$1005,D$22),"") | E26: =IFERROR(SUMIFS(Registro!$N$6:$N$1005,Registro!$I$6:$I$1005,$A26,Registro!$D$6:$D$1005,E$22)/SUMIFS(Registro!$M$6:$M$1005,Registro!$I$6:$I$1005,$A26,Registro!$D$6:$D$1005,E$22),"") | F26: =IFERROR(SUMIFS(Registro!$N$6:$N$1005,Registro!$I$6:$I$1005,$A26,Registro!$D$6:$D$1005,F$22)/SUMIFS(Registro!$M$6:$M$1005,Registro!$I$6:$I$1005,$A26,Registro!$D$6:$D$1005,F$22),"") | G26: =IFERROR(SUMIFS(Registro!$N$6:$N$1005,Registro!$I$6:$I$1005,$A26,Registro!$D$6:$D$1005,G$22)/SUMIFS(Registro!$M$6:$M$1005,Registro!$I$6:$I$1005,$A26,Registro!$D$6:$D$1005,G$22),"") | H26: =IFERROR(SUMIFS(Registro!$N$6:$N$1005,Registro!$I$6:$I$1005,$A26,Registro!$D$6:$D$1005,H$22)/SUMIFS(Registro!$M$6:$M$1005,Registro!$I$6:$I$1005,$A26,Registro!$D$6:$D$1005,H$22),"") | I26: =IFERROR(SUMIFS(Registro!$N$6:$N$1005,Registro!$I$6:$I$1005,$A26,Registro!$D$6:$D$1005,I$22)/SUMIFS(Registro!$M$6:$M$1005,Registro!$I$6:$I$1005,$A26,Registro!$D$6:$D$1005,I$22),"") | ... M26: =IFERROR(SUMIFS(Registro!$N$6:$N$1005,Registro!$I$6:$I$1005,$A26,Registro!$D$6:$D$1005,M$22)/SUMIFS(Registro!$M$6:$M$1005,Registro!$I$6:$I$1005,$A26,Registro!$D$6:$D$1005,M$22),"") | N26: =IFERROR(SUMIFS(Registro!$N$6:$N$1005,Registro!$I$6:$I$1005,$A26,Registro!$D$6:$D$1005,">="&$A$6,Registro!$D$6:$D$1005,"<="&$A$17)/SUMIFS(Registro!$M$6:$M$1005,Registro!$I$6:$I$1005,$A26,Registro!$D$6:$D$1005,">="&$A$6,Registro!$D$6:$D$1005,"<="&$A$17),"") | O26: =IF(Parámetros!B17="",Parámetros!$B$5,Parámetros!B17) -> 0.9551
A27: =Parámetros!A18 -> Cuadrado | B27: =IFERROR(SUMIFS(Registro!$N$6:$N$1005,Registro!$I$6:$I$1005,$A27,Registro!$D$6:$D$1005,B$22)/SUMIFS(Registro!$M$6:$M$1005,Registro!$I$6:$I$1005,$A27,Registro!$D$6:$D$1005,B$22),"") | C27: =IFERROR(SUMIFS(Registro!$N$6:$N$1005,Registro!$I$6:$I$1005,$A27,Registro!$D$6:$D$1005,C$22)/SUMIFS(Registro!$M$6:$M$1005,Registro!$I$6:$I$1005,$A27,Registro!$D$6:$D$1005,C$22),"") | D27: =IFERROR(SUMIFS(Registro!$N$6:$N$1005,Registro!$I$6:$I$1005,$A27,Registro!$D$6:$D$1005,D$22)/SUMIFS(Registro!$M$6:$M$1005,Registro!$I$6:$I$1005,$A27,Registro!$D$6:$D$1005,D$22),"") | E27: =IFERROR(SUMIFS(Registro!$N$6:$N$1005,Registro!$I$6:$I$1005,$A27,Registro!$D$6:$D$1005,E$22)/SUMIFS(Registro!$M$6:$M$1005,Registro!$I$6:$I$1005,$A27,Registro!$D$6:$D$1005,E$22),"") | F27: =IFERROR(SUMIFS(Registro!$N$6:$N$1005,Registro!$I$6:$I$1005,$A27,Registro!$D$6:$D$1005,F$22)/SUMIFS(Registro!$M$6:$M$1005,Registro!$I$6:$I$1005,$A27,Registro!$D$6:$D$1005,F$22),"") | G27: =IFERROR(SUMIFS(Registro!$N$6:$N$1005,Registro!$I$6:$I$1005,$A27,Registro!$D$6:$D$1005,G$22)/SUMIFS(Registro!$M$6:$M$1005,Registro!$I$6:$I$1005,$A27,Registro!$D$6:$D$1005,G$22),"") | H27: =IFERROR(SUMIFS(Registro!$N$6:$N$1005,Registro!$I$6:$I$1005,$A27,Registro!$D$6:$D$1005,H$22)/SUMIFS(Registro!$M$6:$M$1005,Registro!$I$6:$I$1005,$A27,Registro!$D$6:$D$1005,H$22),"") | I27: =IFERROR(SUMIFS(Registro!$N$6:$N$1005,Registro!$I$6:$I$1005,$A27,Registro!$D$6:$D$1005,I$22)/SUMIFS(Registro!$M$6:$M$1005,Registro!$I$6:$I$1005,$A27,Registro!$D$6:$D$1005,I$22),"") | ... M27: =IFERROR(SUMIFS(Registro!$N$6:$N$1005,Registro!$I$6:$I$1005,$A27,Registro!$D$6:$D$1005,M$22)/SUMIFS(Registro!$M$6:$M$1005,Registro!$I$6:$I$1005,$A27,Registro!$D$6:$D$1005,M$22),"") | N27: =IFERROR(SUMIFS(Registro!$N$6:$N$1005,Registro!$I$6:$I$1005,$A27,Registro!$D$6:$D$1005,">="&$A$6,Registro!$D$6:$D$1005,"<="&$A$17)/SUMIFS(Registro!$M$6:$M$1005,Registro!$I$6:$I$1005,$A27,Registro!$D$6:$D$1005,">="&$A$6,Registro!$D$6:$D$1005,"<="&$A$17),"") | O27: =IF(Parámetros!B18="",Parámetros!$B$5,Parámetros!B18) -> 0.9648
A28: =Parámetros!A19 -> Estrella | B28: =IFERROR(SUMIFS(Registro!$N$6:$N$1005,Registro!$I$6:$I$1005,$A28,Registro!$D$6:$D$1005,B$22)/SUMIFS(Registro!$M$6:$M$1005,Registro!$I$6:$I$1005,$A28,Registro!$D$6:$D$1005,B$22),"") | C28: =IFERROR(SUMIFS(Registro!$N$6:$N$1005,Registro!$I$6:$I$1005,$A28,Registro!$D$6:$D$1005,C$22)/SUMIFS(Registro!$M$6:$M$1005,Registro!$I$6:$I$1005,$A28,Registro!$D$6:$D$1005,C$22),"") | D28: =IFERROR(SUMIFS(Registro!$N$6:$N$1005,Registro!$I$6:$I$1005,$A28,Registro!$D$6:$D$1005,D$22)/SUMIFS(Registro!$M$6:$M$1005,Registro!$I$6:$I$1005,$A28,Registro!$D$6:$D$1005,D$22),"") | E28: =IFERROR(SUMIFS(Registro!$N$6:$N$1005,Registro!$I$6:$I$1005,$A28,Registro!$D$6:$D$1005,E$22)/SUMIFS(Registro!$M$6:$M$1005,Registro!$I$6:$I$1005,$A28,Registro!$D$6:$D$1005,E$22),"") | F28: =IFERROR(SUMIFS(Registro!$N$6:$N$1005,Registro!$I$6:$I$1005,$A28,Registro!$D$6:$D$1005,F$22)/SUMIFS(Registro!$M$6:$M$1005,Registro!$I$6:$I$1005,$A28,Registro!$D$6:$D$1005,F$22),"") | G28: =IFERROR(SUMIFS(Registro!$N$6:$N$1005,Registro!$I$6:$I$1005,$A28,Registro!$D$6:$D$1005,G$22)/SUMIFS(Registro!$M$6:$M$1005,Registro!$I$6:$I$1005,$A28,Registro!$D$6:$D$1005,G$22),"") | H28: =IFERROR(SUMIFS(Registro!$N$6:$N$1005,Registro!$I$6:$I$1005,$A28,Registro!$D$6:$D$1005,H$22)/SUMIFS(Registro!$M$6:$M$1005,Registro!$I$6:$I$1005,$A28,Registro!$D$6:$D$1005,H$22),"") | I28: =IFERROR(SUMIFS(Registro!$N$6:$N$1005,Registro!$I$6:$I$1005,$A28,Registro!$D$6:$D$1005,I$22)/SUMIFS(Registro!$M$6:$M$1005,Registro!$I$6:$I$1005,$A28,Registro!$D$6:$D$1005,I$22),"") | ... M28: =IFERROR(SUMIFS(Registro!$N$6:$N$1005,Registro!$I$6:$I$1005,$A28,Registro!$D$6:$D$1005,M$22)/SUMIFS(Registro!$M$6:$M$1005,Registro!$I$6:$I$1005,$A28,Registro!$D$6:$D$1005,M$22),"") | N28: =IFERROR(SUMIFS(Registro!$N$6:$N$1005,Registro!$I$6:$I$1005,$A28,Registro!$D$6:$D$1005,">="&$A$6,Registro!$D$6:$D$1005,"<="&$A$17)/SUMIFS(Registro!$M$6:$M$1005,Registro!$I$6:$I$1005,$A28,Registro!$D$6:$D$1005,">="&$A$6,Registro!$D$6:$D$1005,"<="&$A$17),"") | O28: =IF(Parámetros!B19="",Parámetros!$B$5,Parámetros!B19) -> 0.958
A29: =Parámetros!A20 -> Saferock | B29: =IFERROR(SUMIFS(Registro!$N$6:$N$1005,Registro!$I$6:$I$1005,$A29,Registro!$D$6:$D$1005,B$22)/SUMIFS(Registro!$M$6:$M$1005,Registro!$I$6:$I$1005,$A29,Registro!$D$6:$D$1005,B$22),"") | C29: =IFERROR(SUMIFS(Registro!$N$6:$N$1005,Registro!$I$6:$I$1005,$A29,Registro!$D$6:$D$1005,C$22)/SUMIFS(Registro!$M$6:$M$1005,Registro!$I$6:$I$1005,$A29,Registro!$D$6:$D$1005,C$22),"") | D29: =IFERROR(SUMIFS(Registro!$N$6:$N$1005,Registro!$I$6:$I$1005,$A29,Registro!$D$6:$D$1005,D$22)/SUMIFS(Registro!$M$6:$M$1005,Registro!$I$6:$I$1005,$A29,Registro!$D$6:$D$1005,D$22),"") | E29: =IFERROR(SUMIFS(Registro!$N$6:$N$1005,Registro!$I$6:$I$1005,$A29,Registro!$D$6:$D$1005,E$22)/SUMIFS(Registro!$M$6:$M$1005,Registro!$I$6:$I$1005,$A29,Registro!$D$6:$D$1005,E$22),"") | F29: =IFERROR(SUMIFS(Registro!$N$6:$N$1005,Registro!$I$6:$I$1005,$A29,Registro!$D$6:$D$1005,F$22)/SUMIFS(Registro!$M$6:$M$1005,Registro!$I$6:$I$1005,$A29,Registro!$D$6:$D$1005,F$22),"") | G29: =IFERROR(SUMIFS(Registro!$N$6:$N$1005,Registro!$I$6:$I$1005,$A29,Registro!$D$6:$D$1005,G$22)/SUMIFS(Registro!$M$6:$M$1005,Registro!$I$6:$I$1005,$A29,Registro!$D$6:$D$1005,G$22),"") | H29: =IFERROR(SUMIFS(Registro!$N$6:$N$1005,Registro!$I$6:$I$1005,$A29,Registro!$D$6:$D$1005,H$22)/SUMIFS(Registro!$M$6:$M$1005,Registro!$I$6:$I$1005,$A29,Registro!$D$6:$D$1005,H$22),"") | I29: =IFERROR(SUMIFS(Registro!$N$6:$N$1005,Registro!$I$6:$I$1005,$A29,Registro!$D$6:$D$1005,I$22)/SUMIFS(Registro!$M$6:$M$1005,Registro!$I$6:$I$1005,$A29,Registro!$D$6:$D$1005,I$22),"") | ... M29: =IFERROR(SUMIFS(Registro!$N$6:$N$1005,Registro!$I$6:$I$1005,$A29,Registro!$D$6:$D$1005,M$22)/SUMIFS(Registro!$M$6:$M$1005,Registro!$I$6:$I$1005,$A29,Registro!$D$6:$D$1005,M$22),"") | N29: =IFERROR(SUMIFS(Registro!$N$6:$N$1005,Registro!$I$6:$I$1005,$A29,Registro!$D$6:$D$1005,">="&$A$6,Registro!$D$6:$D$1005,"<="&$A$17)/SUMIFS(Registro!$M$6:$M$1005,Registro!$I$6:$I$1005,$A29,Registro!$D$6:$D$1005,">="&$A$6,Registro!$D$6:$D$1005,"<="&$A$17),"") | O29: =IF(Parámetros!B20="",Parámetros!$B$5,Parámetros!B20) -> 0.9584
A30: =Parámetros!A21 -> Hexágono | B30: =IFERROR(SUMIFS(Registro!$N$6:$N$1005,Registro!$I$6:$I$1005,$A30,Registro!$D$6:$D$1005,B$22)/SUMIFS(Registro!$M$6:$M$1005,Registro!$I$6:$I$1005,$A30,Registro!$D$6:$D$1005,B$22),"") | C30: =IFERROR(SUMIFS(Registro!$N$6:$N$1005,Registro!$I$6:$I$1005,$A30,Registro!$D$6:$D$1005,C$22)/SUMIFS(Registro!$M$6:$M$1005,Registro!$I$6:$I$1005,$A30,Registro!$D$6:$D$1005,C$22),"") | D30: =IFERROR(SUMIFS(Registro!$N$6:$N$1005,Registro!$I$6:$I$1005,$A30,Registro!$D$6:$D$1005,D$22)/SUMIFS(Registro!$M$6:$M$1005,Registro!$I$6:$I$1005,$A30,Registro!$D$6:$D$1005,D$22),"") | E30: =IFERROR(SUMIFS(Registro!$N$6:$N$1005,Registro!$I$6:$I$1005,$A30,Registro!$D$6:$D$1005,E$22)/SUMIFS(Registro!$M$6:$M$1005,Registro!$I$6:$I$1005,$A30,Registro!$D$6:$D$1005,E$22),"") | F30: =IFERROR(SUMIFS(Registro!$N$6:$N$1005,Registro!$I$6:$I$1005,$A30,Registro!$D$6:$D$1005,F$22)/SUMIFS(Registro!$M$6:$M$1005,Registro!$I$6:$I$1005,$A30,Registro!$D$6:$D$1005,F$22),"") | G30: =IFERROR(SUMIFS(Registro!$N$6:$N$1005,Registro!$I$6:$I$1005,$A30,Registro!$D$6:$D$1005,G$22)/SUMIFS(Registro!$M$6:$M$1005,Registro!$I$6:$I$1005,$A30,Registro!$D$6:$D$1005,G$22),"") | H30: =IFERROR(SUMIFS(Registro!$N$6:$N$1005,Registro!$I$6:$I$1005,$A30,Registro!$D$6:$D$1005,H$22)/SUMIFS(Registro!$M$6:$M$1005,Registro!$I$6:$I$1005,$A30,Registro!$D$6:$D$1005,H$22),"") | I30: =IFERROR(SUMIFS(Registro!$N$6:$N$1005,Registro!$I$6:$I$1005,$A30,Registro!$D$6:$D$1005,I$22)/SUMIFS(Registro!$M$6:$M$1005,Registro!$I$6:$I$1005,$A30,Registro!$D$6:$D$1005,I$22),"") | ... M30: =IFERROR(SUMIFS(Registro!$N$6:$N$1005,Registro!$I$6:$I$1005,$A30,Registro!$D$6:$D$1005,M$22)/SUMIFS(Registro!$M$6:$M$1005,Registro!$I$6:$I$1005,$A30,Registro!$D$6:$D$1005,M$22),"") | N30: =IFERROR(SUMIFS(Registro!$N$6:$N$1005,Registro!$I$6:$I$1005,$A30,Registro!$D$6:$D$1005,">="&$A$6,Registro!$D$6:$D$1005,"<="&$A$17)/SUMIFS(Registro!$M$6:$M$1005,Registro!$I$6:$I$1005,$A30,Registro!$D$6:$D$1005,">="&$A$6,Registro!$D$6:$D$1005,"<="&$A$17),"") | O30: =IF(Parámetros!B21="",Parámetros!$B$5,Parámetros!B21) -> 0.9444
A31: Rosado = bajo la meta del grupo; verde = cumple.

Sheet Carta semanal
A1: Carta de control I-MR semanal
A2: LC = rendimiento ponderado del año; σ = MR̄ / d2; LSC / LIC = LC ± 3σ. Semanas ISO (lunes a domingo).
A4: LC (rend. ponderado del año) | B4: ='Resumen mensual'!E18
A5: MR̄ (rango móvil promedio) | B5: =IFERROR(AVERAGE(F12:F64),"")
A6: σ | B6: =IF(B5="","",B5/Parámetros!B8)
A7: LSC = LC + 3σ | B7: =IF(OR(B4="",B6=""),"",B4+3*B6)
A8: LIC = LC − 3σ | B8: =IF(OR(B4="",B6=""),"",B4-3*B6)
A9: Meta ponderada del año | B9: ='Resumen mensual'!F18
A11: Semana | B11: Etiqueta | C11: Consumo (kg) | D11: Producción (kg) | E11: Rend. semanal | F11: Rango móvil (MR) | G11: LC | H11: LSC | I11: LIC | J11: Meta | K11: Semanas seguidas bajo LC | L11: Señal
A12: 1 | B12: ="S"&TEXT(A12,"00") -> S01 | C12: =SUMIFS(Registro!$M$6:$M$1005,Registro!$B$6:$B$1005,Parámetros!$B$4,Registro!$C$6:$C$1005,1) -> 0 | D12: =SUMIFS(Registro!$N$6:$N$1005,Registro!$B$6:$B$1005,Parámetros!$B$4,Registro!$C$6:$C$1005,1) -> 0 | E12: =IF(C12=0,"",D12/C12) | G12: =$B$4 | H12: =$B$7 | I12: =$B$8 | J12: =$B$9 | K12: =IF(OR(E12="",$B$4=""),"",IF(E12<G12,0+1,0)) | L12: =IF(E12="","",IF(AND(H12<>"",OR(E12>H12,E12<I12)),"Fuera de control",IF(K12>=8,"Tendencia: 8+ semanas bajo LC",IF(E12<J12,"Bajo meta","OK"))))
A13: 2 | B13: ="S"&TEXT(A13,"00") -> S02 | C13: =SUMIFS(Registro!$M$6:$M$1005,Registro!$B$6:$B$1005,Parámetros!$B$4,Registro!$C$6:$C$1005,2) -> 0 | D13: =SUMIFS(Registro!$N$6:$N$1005,Registro!$B$6:$B$1005,Parámetros!$B$4,Registro!$C$6:$C$1005,2) -> 0 | E13: =IF(C13=0,"",D13/C13) | F13: =IF(OR(E13="",E12=""),"",ABS(E13-E12)) | G13: =$B$4 | H13: =$B$7 | I13: =$B$8 | J13: =$B$9 | K13: =IF(OR(E13="",$B$4=""),"",IF(E13<G13,N(K12)+1,0)) | L13: =IF(E13="","",IF(AND(H13<>"",OR(E13>H13,E13<I13)),"Fuera de control",IF(K13>=8,"Tendencia: 8+ semanas bajo LC",IF(E13<J13,"Bajo meta","OK"))))
A14: 3 | B14: ="S"&TEXT(A14,"00") -> S03 | C14: =SUMIFS(Registro!$M$6:$M$1005,Registro!$B$6:$B$1005,Parámetros!$B$4,Registro!$C$6:$C$1005,3) -> 0 | D14: =SUMIFS(Registro!$N$6:$N$1005,Registro!$B$6:$B$1005,Parámetros!$B$4,Registro!$C$6:$C$1005,3) -> 0 | E14: =IF(C14=0,"",D14/C14) | F14: =IF(OR(E14="",E13=""),"",ABS(E14-E13)) | G14: =$B$4 | H14: =$B$7 | I14: =$B$8 | J14: =$B$9 | K14: =IF(OR(E14="",$B$4=""),"",IF(E14<G14,N(K13)+1,0)) | L14: =IF(E14="","",IF(AND(H14<>"",OR(E14>H14,E14<I14)),"Fuera de control",IF(K14>=8,"Tendencia: 8+ semanas bajo LC",IF(E14<J14,"Bajo meta","OK"))))
A15: 4 | B15: ="S"&TEXT(A15,"00") -> S04 | C15: =SUMIFS(Registro!$M$6:$M$1005,Registro!$B$6:$B$1005,Parámetros!$B$4,Registro!$C$6:$C$1005,4) -> 0 | D15: =SUMIFS(Registro!$N$6:$N$1005,Registro!$B$6:$B$1005,Parámetros!$B$4,Registro!$C$6:$C$1005,4) -> 0 | E15: =IF(C15=0,"",D15/C15) | F15: =IF(OR(E15="",E14=""),"",ABS(E15-E14)) | G15: =$B$4 | H15: =$B$7 | I15: =$B$8 | J15: =$B$9 | K15: =IF(OR(E15="",$B$4=""),"",IF(E15<G15,N(K14)+1,0)) | L15: =IF(E15="","",IF(AND(H15<>"",OR(E15>H15,E15<I15)),"Fuera de control",IF(K15>=8,"Tendencia: 8+ semanas bajo LC",IF(E15<J15,"Bajo meta","OK"))))
A16: 5 | B16: ="S"&TEXT(A16,"00") -> S05 | C16: =SUMIFS(Registro!$M$6:$M$1005,Registro!$B$6:$B$1005,Parámetros!$B$4,Registro!$C$6:$C$1005,5) -> 0 | D16: =SUMIFS(Registro!$N$6:$N$1005,Registro!$B$6:$B$1005,Parámetros!$B$4,Registro!$C$6:$C$1005,5) -> 0 | E16: =IF(C16=0,"",D16/C16) | F16: =IF(OR(E16="",E15=""),"",ABS(E16-E15)) | G16: =$B$4 | H16: =$B$7 | I16: =$B$8 | J16: =$B$9 | K16: =IF(OR(E16="",$B$4=""),"",IF(E16<G16,N(K15)+1,0)) | L16: =IF(E16="","",IF(AND(H16<>"",OR(E16>H16,E16<I16)),"Fuera de control",IF(K16>=8,"Tendencia: 8+ semanas bajo LC",IF(E16<J16,"Bajo meta","OK"))))
A17: 6 | B17: ="S"&TEXT(A17,"00") -> S06 | C17: =SUMIFS(Registro!$M$6:$M$1005,Registro!$B$6:$B$1005,Parámetros!$B$4,Registro!$C$6:$C$1005,6) -> 0 | D17: =SUMIFS(Registro!$N$6:$N$1005,Registro!$B$6:$B$1005,Parámetros!$B$4,Registro!$C$6:$C$1005,6) -> 0 | E17: =IF(C17=0,"",D17/C17) | F17: =IF(OR(E17="",E16=""),"",ABS(E17-E16)) | G17: =$B$4 | H17: =$B$7 | I17: =$B$8 | J17: =$B$9 | K17: =IF(OR(E17="",$B$4=""),"",IF(E17<G17,N(K16)+1,0)) | L17: =IF(E17="","",IF(AND(H17<>"",OR(E17>H17,E17<I17)),"Fuera de control",IF(K17>=8,"Tendencia: 8+ semanas bajo LC",IF(E17<J17,"Bajo meta","OK"))))
A18: 7 | B18: ="S"&TEXT(A18,"00") -> S07 | C18: =SUMIFS(Registro!$M$6:$M$1005,Registro!$B$6:$B$1005,Parámetros!$B$4,Registro!$C$6:$C$1005,7) -> 0 | D18: =SUMIFS(Registro!$N$6:$N$1005,Registro!$B$6:$B$1005,Parámetros!$B$4,Registro!$C$6:$C$1005,7) -> 0 | E18: =IF(C18=0,"",D18/C18) | F18: =IF(OR(E18="",E17=""),"",ABS(E18-E17)) | G18: =$B$4 | H18: =$B$7 | I18: =$B$8 | J18: =$B$9 | K18: =IF(OR(E18="",$B$4=""),"",IF(E18<G18,N(K17)+1,0)) | L18: =IF(E18="","",IF(AND(H18<>"",OR(E18>H18,E18<I18)),"Fuera de control",IF(K18>=8,"Tendencia: 8+ semanas bajo LC",IF(E18<J18,"Bajo meta","OK"))))
A19: 8 | B19: ="S"&TEXT(A19,"00") -> S08 | C19: =SUMIFS(Registro!$M$6:$M$1005,Registro!$B$6:$B$1005,Parámetros!$B$4,Registro!$C$6:$C$1005,8) -> 0 | D19: =SUMIFS(Registro!$N$6:$N$1005,Registro!$B$6:$B$1005,Parámetros!$B$4,Registro!$C$6:$C$1005,8) -> 0 | E19: =IF(C19=0,"",D19/C19) | F19: =IF(OR(E19="",E18=""),"",ABS(E19-E18)) | G19: =$B$4 | H19: =$B$7 | I19: =$B$8 | J19: =$B$9 | K19: =IF(OR(E19="",$B$4=""),"",IF(E19<G19,N(K18)+1,0)) | L19: =IF(E19="","",IF(AND(H19<>"",OR(E19>H19,E19<I19)),"Fuera de control",IF(K19>=8,"Tendencia: 8+ semanas bajo LC",IF(E19<J19,"Bajo meta","OK"))))
A20: 9 | B20: ="S"&TEXT(A20,"00") -> S09 | C20: =SUMIFS(Registro!$M$6:$M$1005,Registro!$B$6:$B$1005,Parámetros!$B$4,Registro!$C$6:$C$1005,9) -> 0 | D20: =SUMIFS(Registro!$N$6:$N$1005,Registro!$B$6:$B$1005,Parámetros!$B$4,Registro!$C$6:$C$1005,9) -> 0 | E20: =IF(C20=0,"",D20/C20) | F20: =IF(OR(E20="",E19=""),"",ABS(E20-E19)) | G20: =$B$4 | H20: =$B$7 | I20: =$B$8 | J20: =$B$9 | K20: =IF(OR(E20="",$B$4=""),"",IF(E20<G20,N(K19)+1,0)) | L20: =IF(E20="","",IF(AND(H20<>"",OR(E20>H20,E20<I20)),"Fuera de control",IF(K20>=8,"Tendencia: 8+ semanas bajo LC",IF(E20<J20,"Bajo meta","OK"))))
A21: 10 | B21: ="S"&TEXT(A21,"00") -> S10 | C21: =SUMIFS(Registro!$M$6:$M$1005,Registro!$B$6:$B$1005,Parámetros!$B$4,Registro!$C$6:$C$1005,10) -> 0 | D21: =SUMIFS(Registro!$N$6:$N$1005,Registro!$B$6:$B$1005,Parámetros!$B$4,Registro!$C$6:$C$1005,10) -> 0 | E21: =IF(C21=0,"",D21/C21) | F21: =IF(OR(E21="",E20=""),"",ABS(E21-E20)) | G21: =$B$4 | H21: =$B$7 | I21: =$B$8 | J21: =$B$9 | K21: =IF(OR(E21="",$B$4=""),"",IF(E21<G21,N(K20)+1,0)) | L21: =IF(E21="","",IF(AND(H21<>"",OR(E21>H21,E21<I21)),"Fuera de control",IF(K21>=8,"Tendencia: 8+ semanas bajo LC",IF(E21<J21,"Bajo meta","OK"))))
